Workbook

Sheet PANEL DE CONTROL
A1: PANEL DE CONTROL BOOKING M$
B3: Unidad de Negocio | C3: Booking 2023 | E3: Booking 2024 | G3: Meta 2025 | I3: Proy 2025 vs Resultado 2024 | J3: Meta a Nov 2025 | L3: Booking logrado al | N3: Var | O3: Pronóstico Diciembre | P3: Pronóstico Resultado Anual | R3: Var Meta 2025 | S3: Var 2024 | X3: 1000
L4: ='METAS VTAS Y OCS'!C2 -> 46022
B5: Sistemas Normativos | C5: =516146/X3 -> 516.146 | E5: =1032308/X3 -> 1032.308 | G5: 1075 | I5: =(G5-E5)/E5 -> 0.041355874 | J5: ='METAS VTAS Y OCS'!M5 -> 1013 | L5: ='METAS VTAS Y OCS'!N7 -> 1527.787 | N5: =(L5-J5)/J5 -> 0.50818065 | P5: =L5+O5 -> 1527.787 | R5: =(L5-G5)/G5 -> 0.42119721 | S5: =(P5-E5)/E5 -> 0.47997206
B6: SCADAS Y SAC | C6: =175255/X3 -> 175.255 | E6: =(250294+447409)/X3 -> 697.703 | G6: 1281 | I6: =(G6-E6)/E6 -> 0.83602478 | J6: ='METAS VTAS Y OCS'!M11 -> 1269.5 | L6: ='METAS VTAS Y OCS'!N13 -> #REF! | N6: =(L6-J6)/J6 -> #REF! | P6: =L6+O6 -> #REF! | R6: =(L6-G6)/G6 -> #REF! | S6: =(P6-E6)/E6 -> #REF!
B7: PAC | C7: =1047538/X3 -> 1047.538 | E7: =143825/X3 -> 143.825 | G7: 1319 | I7: =(G7-E7)/E7 -> 8.1708674 | J7: ='METAS VTAS Y OCS'!M17 -> 1195.95 | L7: ='METAS VTAS Y OCS'!N19 -> 528.556 | N7: =(L7-J7)/J7 -> -0.55804507 | P7: =L7+O7 -> 528.556 | R7: =(L7-G7)/G7 -> -0.59927521 | S7: =(P7-E7)/E7 -> 2.6749939
B8: Total | C8: =SUM(C5:C7) -> 1738.939 | E8: =SUM(E5:E7) -> 1873.836 | G8: =SUM(G5:H7) -> 3675 | I8: =(G8-E8)/E8 -> 0.96121752 | J8: =SUM(J5:K7) -> 3478.45 | L8: =SUM(L5:L7) -> #REF! | N8: =(L8-J8)/J8 -> #REF! | O8: =SUM(O5:O7) -> 0 | P8: =SUM(P5:P7) -> #REF! | R8: =(P8-G8)/G8 -> #REF! | S8: =(P8-E8)/E8 -> #REF!
B10: Supcon - Sistemas
B11: Unidad de Negocio | C11: Pronóstico 2026 | G11: Total
C12: Q1 | D12: Q2 | E12: Q3 | F12: Q4
B13: Sistemas Normativos | C13: 1120 | D13: 243 | E13: 68 | F13: 0 | G13: =SUM(C13:F13) -> 1431
B14: SCADAS Y SAC | C14: 278 | D14: 310 | E14: 35 | F14: 22 | G14: =SUM(C14:F14) -> 645
B15: PAC | C15: 471 | D15: 67 | E15: 7 | F15: 15 | G15: =SUM(C15:F15) -> 560
B16: Total | C16: =SUM(C13:C15) -> 1869 | D16: =SUM(D13:D15) -> 620 | E16: =SUM(E13:E15) -> 110 | G16: =SUM(C16:F16) -> 2599
D20: 1775
D21: 700

Sheet METAS VTAS Y OCS
B1: METAS VENTA Y OCS 2025 MCLP
B2: Fecha actualización | C2: 46022
B3: Normativo | C3: Enero | D3: Febrero | E3: Marzo | F3: Abril | G3: Mayo | H3: Junio | I3: Julio | J3: Agosto | K3: Septiembre | L3: Octubre | M3: Noviembre | N3: Diciembre | O3: Total | Q3: Facturación
B4: Meta acumulada | C4: =O4/12 -> 89.583333 | D4: =$O$4/12+C4 -> 179.16667 | E4: =$O$4/12+D4 -> 268.75 | F4: =$O$4/12+E4 -> 358.33333 | G4: =$O$4/12+F4 -> 447.91667 | H4: =$O$4/12+G4 -> 537.5 | I4: =$O$4/12+H4 -> 627.08333 | J4: =$O$4/12+I4 -> 716.66667 | K4: =$O$4/12+J4 -> 806.25 | ... N4: =$O$4/12+M4 -> 1075 | O4: 1075 | Q4: 417
B5: Proyección anual | C5: 6 | D5: =C5+30 -> 36 | E5: =D5+305 -> 341 | F5: =E5+19 -> 360 | G5: =F5+20 -> 380 | H5: =G5+31 -> 411 | I5: =H5+65 -> 476 | J5: =I5+161 -> 637 | K5: =J5+72 -> 709 | L5: =K5+54 -> 763 | M5: =L5+250 -> 1013 | N5: =M5+62 -> 1075
B6: OCs acumuladas | C6: =C7 -> 10.808 | D6: =C6+D7 -> 13.127 | E6: =D6+E7 -> 128.463 | F6: =E6+F7 -> 230.042 | G6: =F6+G7 -> 405.108 | H6: =G6+H7 -> 405.108 | I6: =H6+I7 -> 926.181 | J6: =I6+J7 -> 982.111 | K6: =J6+K7 -> 1040.387 | ... M6: =L6+M7 -> 1527.787 | O6: =SUM(C6:N6) -> 6964.813
B7: OCs mensual | C7: =(E65+E67)/1000 -> 10.808 | D7: =(E72)/1000 -> 2.319 | E7: =(E80+E81+E84+E85+E86)/1000 -> 115.336 | F7: =(E88+E89+E90+E91+E92+E96+E97+E98)/1000 -> 101.579 | G7: =(E101+E102+E103)/1000 -> 175.066 | H7: =(E105)/1000 -> 0 | I7: =(E112+E114+E116)/1000 -> 521.073 | J7: =(E119+E121+E122)/1000 -> 55.93 | K7: =(E126+E127+E129+E130+E131+E132)/1000 -> 58.276 | L7: =(E135+E136+E137+E138+E139+E140+E141)/1000 -> 255.304 | M7: =(E144+E145+E146+E147+E148+E152+E157+E158+E159+E160)/1000 -> 232.096 | N7: =SUM(C7:M7) -> 1527.787
B9: SCADAS Y SAC | C9: Enero | D9: Febrero | E9: Marzo | F9: Abril | G9: Mayo | H9: Junio | I9: Julio | J9: Agosto | K9: Septiembre | L9: Octubre | M9: Noviembre | N9: Diciembre | O9: Total | Q9: Facturación
B10: Meta acumulada | C10: =O10/12 -> 106.75 | D10: =$O$10/12+C10 -> 213.5 | E10: =$O$10/12+D10 -> 320.25 | F10: =$O$10/12+E10 -> 427 | G10: =$O$10/12+F10 -> 533.75 | H10: =$O$10/12+G10 -> 640.5 | I10: =$O$10/12+H10 -> 747.25 | J10: =$O$10/12+I10 -> 854 | K10: =$O$10/12+J10 -> 960.75 | ... N10: =$O$10/12+M10 -> 1281 | O10: 1281 | Q10: 608
B11: Proyección anual | C11: 46.75 | D11: =C11+7.5 -> 54.25 | E11: =D11+57.5 -> 111.75 | F11: =E11+25.5 -> 137.25 | G11: =F11+61.5 -> 198.75 | H11: =G11+170 -> 368.75 | I11: =H11+52.25 -> 421 | J11: =I11+146 -> 567 | K11: =J11+473 -> 1040 | L11: =K11+199.5 -> 1239.5 | M11: =L11+30 -> 1269.5 | N11: =M11+11.25 -> 1280.75
B12: OCs acumuladas | C12: =C13 -> 0.922 | D12: =C12+D13 -> 55.349 | E12: =D12+E13 -> 140.245 | F12: =E12+F13 -> 140.245 | G12: =F12+G13 -> 140.245 | H12: =G12+H13 -> 332.747 | I12: =H12+I13 -> 372.391 | J12: =I12+J13 -> 374.115 | K12: =J12+K13 -> 374.115 | ... M12: =L12+M13 -> #REF! | O12: =SUM(C12:N12) -> #REF!
B13: OCs mensual | C13: =E66/1000 -> 0.922 | D13: =(E71+E73+E74+E75+E77)/1000 -> 54.427 | E13: =(E82)/1000 -> 84.896 | F13: 0 | G13: 0 | H13: =(E107+E108)/1000 -> 192.502 | I13: =(E113)/1000 -> 39.644 | J13: =(E124)/1000 -> 1.724 | K13: 0 | L13: =E134/1000 -> 38.334 | M13: =(E153+E163+#REF!)/1000 -> #REF! | N13: =SUM(C13:M13) -> #REF!
B15: PAC | C15: Enero | D15: Febrero | E15: Marzo | F15: Abril | G15: Mayo | H15: Junio | I15: Julio | J15: Agosto | K15: Septiembre | L15: Octubre | M15: Noviembre | N15: Diciembre | O15: Total | Q15: Facturación
B16: Meta acumulada | C16: =O16/12 -> 109.91667 | D16: =$O$16/12+C16 -> 219.83333 | E16: =$O$16/12+D16 -> 329.75 | F16: =$O$16/12+E16 -> 439.66667 | G16: =$O$16/12+F16 -> 549.58333 | H16: =$O$16/12+G16 -> 659.5 | I16: =$O$16/12+H16 -> 769.41667 | J16: =$O$16/12+I16 -> 879.33333 | K16: =$O$16/12+J16 -> 989.25 | ... N16: =$O$16/12+M16 -> 1319 | O16: 1319 | Q16: 531
B17: Proyección anual | C17: =38.2 -> 38.2 | D17: =12+C17 -> 50.2 | E17: =D17+35 -> 85.2 | F17: =E17+126.55 -> 211.75 | G17: =F17+180 -> 391.75 | H17: =G17+226 -> 617.75 | I17: =H17+89.7 -> 707.45 | J17: =I17+106.5 -> 813.95 | K17: =J17+89 -> 902.95 | L17: =K17+232 -> 1134.95 | M17: =L17+61 -> 1195.95 | N17: =M17+122.8 -> 1318.75
B18: OCs acumuladas | C18: =C19 -> 11.69 | D18: =C18+D19 -> 96.508 | E18: =D18+E19 -> 133.355 | F18: =E18+F19 -> 194.915 | G18: =F18+G19 -> 198.342 | H18: =G18+H19 -> 223.826 | I18: =H18+I19 -> 264.879 | J18: =I18+J19 -> 294.598 | K18: =J18+K19 -> 330.71 | ... M18: =L18+M19 -> 528.556 | O18: =SUM(C18:N18) -> 2608.089
B19: OCs mensual | C19: =E68/1000 -> 11.69 | D19: =(E70+E76+E78)/1000 -> 84.818 | E19: =(E83)/1000 -> 36.847 | F19: =(E93+E94+E95)/1000 -> 61.56 | G19: =(E100)/1000 -> 3.427 | H19: =(E106+E109)/1000 -> 25.484 | I19: =(E111+E115)/1000 -> 41.053 | J19: =(E118+E120+E123)/1000 -> 29.719 | K19: =E128/1000 -> 36.112 | L19: 0 | M19: =(E143+E149+E150+E151+E154+E155+E156+E161+E162)/1000 -> 197.846 | N19: =SUM(C19:M19) -> 528.556
C37: 1
B38: TOTAL | C38: Enero | D38: Febrero | E38: Marzo | F38: Abril | G38: Mayo | H38: Junio | I38: Julio | J38: Agosto | K38: Septiembre | L38: Octubre | M38: Noviembre | N38: Diciembre | O38: Total | Q38: Facturación | R38: 1% de la venta
B39: Meta acumulada | C39: =C4+C10+C16 -> 306.25 | D39: =D4+D10+D16 -> 612.5 | E39: =E4+E10+E16 -> 918.75 | F39: =F4+F10+F16 -> 1225 | G39: =G4+G10+G16 -> 1531.25 | H39: =H4+H10+H16 -> 1837.5 | I39: =I4+I10+I16 -> 2143.75 | J39: =J4+J10+J16 -> 2450 | ... N39: =N4+N10+N16 -> 3675 | O39: =N39 -> 3675 | Q39: =Q4+Q10+Q16 -> 1556 | R39: =N39*1% -> 36.75
B40: Proyección anual | C40: =(C5+C11+C17)*$C$37 -> 90.95 | D40: =(D5+D11+D17)*$C$37 -> 140.45 | E40: =(E5+E11+E17)*$C$37 -> 537.95 | F40: =(F5+F11+F17)*$C$37 -> 709 | G40: =(G5+G11+G17)*$C$37 -> 970.5 | H40: =(H5+H11+H17)*$C$37 -> 1397.5 | I40: =(I5+I11+I17)*$C$37 -> 1604.45 | J40: =(J5+J11+J17)*$C$37 -> 2017.95 | ... N40: =(N5+N11+N17)*$C$37 -> 3674.5
B41: OCs acumuladas | C41: =C42 -> 23.42 | D41: =C41+D42 -> 164.984 | E41: =D41+E42 -> 402.063 | F41: =E41+F42 -> 565.202 | G41: =F41+G42 -> 743.695 | H41: =G41+H42 -> 961.681 | I41: =H41+I42 -> 1563.451 | J41: =I41+J42 -> 1650.824 | K41: =J41+K42 -> 1745.212 | ... M41: =L41+M42 -> #REF!
B42: OCs | C42: =(C7+C13+C19)*$C$37 -> 23.42 | D42: =(D7+D13+D19)*$C$37 -> 141.564 | E42: =(E7+E13+E19)*$C$37 -> 237.079 | F42: =(F7+F13+F19)*$C$37 -> 163.139 | G42: =(G7+G13+G19)*$C$37 -> 178.493 | H42: =(H7+H13+H19)*$C$37 -> 217.986 | I42: =(I7+I13+I19)*$C$37 -> 601.77 | J42: =(J7+J13+J19)*$C$37 -> 87.373 | ... M42: =(M7+M13+M19)*$C$37 -> #REF! | N42: =SUM(C42:M42) -> #REF! | O42: =SUM(C42:N42) -> #REF!
B64: Cliente | C64: OT | D64: UF | E64: M$ | F64: Costo Bruto M$ | G64: Margen Bruto $ | H64: Costo Neto M$ | I64: Margen Neto $ | J64: Línea | K64: Descripcion | N64: 1
B65: Enor Chile | C65: 2351433 | D65: 250 | E65: =9694/N64 -> 9694 | F65: 6321 | G65: 3283 | H65: 7203 | I65: 2401 | J65: Normativo | K65: Adicionales Servicio de adecuacion para señales SITR
B66: Norvind | C66: 2348146 | D66: 24 | E66: =922/N64 -> 922 | F66: 486 | G66: 436 | H66: 757 | I66: 165 | J66: Scada y SAC | K66: Servicio de Mantenimiento Preventivo SCADA
B67: Melon | C67: 2353624 | D67: 29 | E67: =1114/N64 -> 1114 | F67: 495 | G67: 619 | H67: 838 | I67: 276 | J67: Normativo | K67: Diagnostico remoto para detectar fallas de comunicación en sistema EDAC. | N67: -
B68: Celeo | C68: 7070-00 | D68: 305 | E68: =11690/N64 -> 11690 | F68: 8211 | G68: 2929 | H68: 8211 | I68: 3480 | J68: PAC | K68: suministro de dos (2) GPS Kronos
B69: Ordenes de Compra Enero | D69: =SUM(D65:D68) -> 608 | E69: =SUM(E65:E68) -> 23420 | F69: =SUM(F65:F68) -> 15513 | G69: =SUM(G65:G68) -> 7267 | H69: =SUM(H65:H68) -> 17009 | I69: =SUM(I65:I68) -> 6322
B70: Grupo Cerro | C70: 8349-00 | D70: 1243 | E70: =43639/N64 -> 43639 | F70: 30236 | G70: 13448 | H70: 36075 | I70: 12420 | J70: PAC | K70: Parametrizar 7 Protecciones
B71: Hidroelectrica Puclaro | C71: 1199458 | D71: 187 | E71: =6709/N64 -> 6709 | F71: 5028 | G71: 1681 | H71: 5380 | I71: 1329 | J71: Scada y SAC | K71: Serv Implementacion Control de Alabes remoto
B72: Generadora Metropolitana | C72: 8350-00 | D72: 60 | E72: =2319/N64 -> 2319 | F72: 1207 | G72: 1112 | H72: 1962 | I72: 357 | J72: Normativo | K72: Levantamiento y revision instalación PMU
B73: Hidroelectrica Rio Colorado | C73: 5185-00 | D73: 256 | E73: =9337/N64 -> 9337 | F73: 5700 | G73: 3637 | H73: 8867 | I73: 470 | J73: Scada y SAC | K73: Integración Central Rio Colorado
B74: Hidroelectrica Mallarauco | C74: 1192884 | D74: 49 | E74: =1802/N64 -> 1802 | F74: 1134 | G74: 668 | H74: 1428 | I74: 374 | J74: Scada y SAC | K74: Suministro, montaje y configuración de tarjeta de señales digitales | N74: -
B75: Norvind | C75: 2348177 | D75: 552 | E75: =21334/N64 -> 21334 | F75: 11644 | G75: 9689 | H75: 17387 | I75: 3947 | J75: Scada y SAC | K75: Servicio de Mantenimiento Preventivo SCADA
B76: Guacolda Energia SpA | C76: 8351-00 | D76: 350 | E76: =13527/N64 -> 13527 | F76: 7016 | G76: 6511 | H76: 10697 | I76: 2830 | J76: PAC | K76: Normalizar las protecciones de la planta TG Huasco:
B77: Colbun | C77: 8352-00 | D77: 405 | E77: =15245/N64 -> 15245 | F77: 10610 | G77: 4635 | H77: 12883 | I77: 2362 | J77: Scada y SAC | K77: Integracion de señales parque eolico Totoral
B78: Transelec | C78: 1188167 | D78: 715 | E78: =27652/N64 -> 27652 | F78: 14346 | G78: 13306 | H78: 16342 | I78: 11310 | J78: PAC | K78: Suministros modulo IO y servicios S/E Itahue y Quillota
B79: Ordenes de Compra Febrero | D79: =SUM(D70:D78) -> 3817 | E79: =SUM(E70:E78) -> 141564 | F79: =SUM(F70:F78) -> 86921 | G79: =SUM(G70:G78) -> 54687 | H79: =SUM(H70:H78) -> 111021 | I79: =SUM(I70:I78) -> 35399
B80: Metro | C80: 2321177 | D80: 736.6 | E80: =28468/N64 -> 28468 | F80: 12365 | G80: 16103 | H80: 14846 | I80: 13622 | J80: Normativo | K80: Mant. Sistema Desconexion Automatica Cargas
...

Sheet PROYECCIÓN
A1: PROYECCIÓN BOOKING | AD1: 1 | AE1: Posicionamiento y cotización
AD2: 0 | AE2: Filtro
B3: MES | D3: CLIENTE | E3: PROYECTO | F3: 1 | G3: MONTO | H3: % | I3: VENTA CON % | J3: ETAPA | L3: ENE | M3: FEB | N3: MAR | O3: ABR | P3: MAY | Q3: JUN | R3: JUL | S3: AGO | T3: SEPT | U3: ENE | V3: FEB | W3: MAR | X3: ABR | Y3: MAY | Z3: JUN | AA3: JUL | AB3: AGO | AC3: SEPT | AD3: OCT | AE3: NOV | AF3: DIC | AG3: ENE | AH3: FEB | AI3: MAR | AJ3: ABR | AK3: MAY | AL3: JUN | AM3: JUL | AN3: AGO | AO3: SEPT | AP3: OCT | AQ3: NOV | AR3: DIC
B4: ENERO | D4: Enor | E4: Adicional adecuaciones SITR | F4: 0 | G4: =F4*13.5 -> 0 | H4: 1 | I4: =G4*H4 -> 0 | W4: =I4*30% -> 0 | X4: =I4*70% -> 0
F5: 0 | X5: =6*H4 -> 6
B6: MARZO | D6: Metro | E6: Mantenimiento EDAC | F6: 0 | G6: =F6*30 -> 0 | H6: 1 | I6: =G6*H6 -> 0 | X6: =I6/5 -> 0 | Y6: =X6 -> 0 | Z6: =Y6 -> 0 | AA6: =Z6 -> 0 | AB6: =AA6 -> 0
F7: 0
B8: MARZO | D8: Generadora Metropolitana | E8: Visita Levantamiento - PMU - Planta CEME 1 | F8: 0 | G8: =F8*2.5 -> 0 | H8: 0.75 | I8: =G8*H8 -> 0 | X8: =I8 -> 0
F9: 0
B10: MARZO | D10: Repsol | E10: EDAGxCE | F10: 0 | G10: =F10*44 -> 0 | H10: 1 | I10: =G10*H10 -> 0 | J10: Cierre | X10: =I10*20% -> 0 | Y10: =I10*15% -> 0 | Z10: =I10*15% -> 0 | AA10: =I10*15% -> 0 | AB10: =I10*25% -> 0 | AC10: =I10*5% -> 0 | AD10: =I10*5% -> 0
F11: 0 | X11: =F10*H10*1.1 -> 0 | Y11: =F10*H10*5.4 -> 0 | Z11: =F10*H10*6.5 -> 0 | AA11: =F10*H10*12.5 -> 0 | AB11: =F10*H10*2.6 -> 0
B12: MARZO | D12: Transelec | E12: Cambio PDC Maitencillo | F12: 0 | G12: =F12*6.5 -> 0 | H12: 1 | I12: =G12*H12 -> 0 | J12: Cierre | K12: Añadir flujo | X12: =I12 -> 0
F13: 0 | X13: =X12*0.5 -> 0
B14: ABRIL | D14: Cementos Melon | E14: Mtto EDAC | F14: 0 | G14: =F14*10 -> 0 | H14: 1 | I14: =G14*H14 -> 0 | J14: Posicionamiento | Y14: =I14 -> 0
F15: 0 | Y15: =Y14*0.5 -> 0
B16: FEBRERO | D16: X-elio | E16: Servicio de configuración de enlaces y pruebas de operatividad EDAGxCE | F16: 0 | G16: =F16*3 -> 0 | H16: 0.7 | I16: =G16*H16 -> 0 | X16: =I16 -> 0
F17: 0
B18: ABRIL | D18: Amanecer Solar | E18: Adicionales SLRP | F18: 0 | G18: =F18*8 -> 0 | H18: 1 | I18: =G18*H18 -> 0 | J18: Cierre | Z18: =I18 -> 0
F19: 0
B20: MAYO | D20: Hidropalmar | E20: PMU | F20: 0 | G20: =F20*31 -> 0 | H20: 0.9 | I20: =G20*H20 -> 0 | J20: Cierre | K20: Corregir flujo | AA20: =I20*25% -> 0 | AB20: =I20*20% -> 0 | AC20: =I20*50% -> 0 | AD20: =I20*5% -> 0
F21: 0 | AC21: =12.6*H20 -> 11.34 | AE21: =H20*13.5 -> 12.15
B22: MAYO | D22: Transelec | E22: PMU Ancud | F22: 0 | G22: =F22*77 -> 0 | H22: 0.9 | I22: =G22*H22 -> 0 | J22: Cierre | AA22: =I22*10% -> 0 | AB22: =I22*10% -> 0 | AC22: =I22*10% -> 0 | AD22: =I22*15% -> 0 | AE22: =I22*55% -> 0
F23: 0 | AB23: =F22*H22*3.4 -> 0 | AD23: =F22*H22*13 -> 0 | AE23: =F22*H22*13 -> 0 | AF23: =F22*H22*12 -> 0
B24: MAYO | D24: Transelec | E24: PDC Zona Norte | F24: 0 | G24: =F24*72 -> 0 | H24: 0.7 | I24: =G24*H24 -> 0 | J24: Cierre | AA24: =I24*10% -> 0 | AB24: =I24*15% -> 0 | AC24: =I24*20% -> 0 | AE24: =I24*20% -> 0 | AF24: =I24*35% -> 0
F25: 0 | AA25: =F24*H24*0.9 -> 0 | AB25: =F24*H24*1 -> 0 | AD25: =F24*H24*4 -> 0 | AE25: =F24*H24*23.5 -> 0 | AF25: =F24*H24*17 -> 0 | AG25: =F24*H24*5.3 -> 0
B26: NORMATIVO | F26: 1
B27: JULIO | D27: Metro | E27: Mantenimiento EDAC | F27: 0 | G27: =F27*230 -> 0 | H27: 0.9 | I27: =G27*H27 -> 0 | J27: Cierre | AC27: =I27/24 -> 0 | AD27: =AC27 -> 0 | AE27: =AD27 -> 0 | AF27: =AE27 -> 0 | AG27: =AF27 -> 0 | AH27: =AG27 -> 0 | AI27: =AH27 -> 0 | AJ27: =AI27 -> 0 | AK27: =AJ27 -> 0 | AL27: =AK27 -> 0
F28: 0
B29: MAYO | D29: UTFSM | E29: Suministro OPAL | F29: 0 | G29: =F29*22 -> 0 | H29: 0.5 | I29: =G29*H29 -> 0 | J29: Cierre | K29: Añadir flujo
F30: 0
B31: JUNIO | D31: Generadora | E31: Faltantes PMU Nueva Renca | F31: =AD2 -> 0 | G31: =F31*20 -> 0 | H31: 0.6 | I31: =G31*H31 -> 0 | J31: Filtro | AC31: =I31*25% -> 0 | AD31: =I31*20% -> 0 | AE31: =I31*50% -> 0 | AF31: =I31*5% -> 0
F32: =AD2 -> 0 | AE32: =12.6*H31*F32 -> 0 | AG32: =H31*13.5*F32 -> 0
B33: AGOSTO | D33: Mainstream | E33: 5 x EDAG x CE | F33: 0 | G33: =F33*180 -> 0 | H33: 0.5 | I33: =G33*H33 -> 0 | J33: Perdido | K33: Actualizar por ingeteam | AF33: =I33*30% -> 0 | AJ33: =I33*30% -> 0 | AL33: =I33*40% -> 0
F34: 0 | AD34: =F33*H33*1 -> 0 | AG34: =F33*H33*21 -> 0 | AI34: =F33*H33*45 -> 0 | AJ34: =F33*H33*27 -> 0 | AK34: =F33*H33*8 -> 0
B35: AGOSTO | D35: AES | E35: EDAG Bess Arenales | F35: 0 | G35: =F35*100 -> 0 | H35: 0.5 | I35: =G35*H35 -> 0 | J35: Cierre | K35: Actualizar flujo | AC35: =I35*10%*65% -> 0 | AD35: =I35*15%*65% -> 0 | AE35: =I35*20%*65%+I35*70%*35% -> 0 | AF35: =I35*25%*65% -> 0 | AG35: =I35*25%*65%+I35*30%*35% -> 0 | AH35: =I35*5%*65% -> 0
F36: 0 | AC36: =F36*H35*0.8 -> 0 | AF36: =F36*H35*7.7 -> 0 | AG36: =F36*H35*30 -> 0 | AH36: =F36*H35*9 -> 0
B37: Perdido | D37: Sonnedix | E37: PMU Meseta de los Andes | F37: 0 | G37: =F37*32 -> 0 | H37: 0.6 | I37: =G37*H37 -> 0 | J37: Cierre | AC37: =I37*20% -> 0 | AD37: =I37*10% -> 0 | AE37: =I37*15% -> 0 | AF37: =I37*15% -> 0 | AG37: =I37*20% -> 0 | AH37: =I37*20% -> 0
F38: 0 | AD38: =F37*H37*3.2 -> 0 | AE38: =F37*H37*2.5 -> 0 | AF38: =F37*H37*2.5 -> 0 | AG38: =F37*H37*5 -> 0 | AH38: =F37*H37*5.6 -> 0 | AI38: =F37*H37*3.6 -> 0
B39: JULIO | D39: Cabo Leones II Fase 2 | E39: PMU | F39: =AD2 -> 0 | G39: =F39*30 -> 0 | H39: 0.25 | I39: =G39*H39 -> 0 | J39: Filtro | K39: 0.5 | AD39: =I39*25% -> 0 | AE39: =I39*20% -> 0 | AF39: =I39*50% -> 0 | AG39: =I39*5% -> 0
F40: =AD2 -> 0 | AF40: =12.6*H39*F40 -> 0 | AH40: =H39*13.5*F40 -> 0
...

Sheet PRESUPUESTO
A1: PRESUPUESTO DE GASTOS OPERACIONALES
B4: Código | C4: Ítem | D4: Descripción | E4: Presupuesto Inicial | F4: Reasignado en Junio | G4: Reasignación Final | H4: Real a Noviembre | I4: Saldo | J4: Presupuesto 2026
B5: 138 | C5: Personnel & Related | D5: Curso Área Comercial - Protecciones eléctricas | E5: 0 | F5: 3100000 | G5: =F5 -> 3100000 | H5: 1653805 | I5: =G5-H5 -> 1446195
B6: 139 | C6: Personnel & Related | D6: Curso Área Comercial - Mercado eléctrico y otro -> Servicios Maximiliano Arne | E6: 0 | F6: 3000000 | G6: =F6 -> 3000000 | H6: 1791267 | I6: =G6-H6 -> 1208733
B7: 106 | C7: Personnel & Related | D7: Curso Área Comercial - Diseño de C&P y Diseño Redes | E7: 0 | F7: 0 | G7: =F7 -> 0 | H7: 0 | I7: =G7-H7 -> 0
B8: 26 | C8: Personnel & Related | D8: Curso Área Comercial - Academia de Prospección | E8: 0 | F8: 0 | G8: =F8 -> 0 | H8: 0 | I8: =G8-H8 -> 0
B9: 42 | C9: Promotion | D9: Vestuario | E9: 750000 | F9: 750000 | G9: =F9 -> 750000 | H9: 1033558 | I9: =G9-H9 -> -283558
B10: 43 | C10: Promotion | D10: Tarjetas | E10: 0 | F10: 0 | G10: =F10 -> 0 | H10: 0 | I10: =G10-H10 -> 0
B11: 127 | C11: Promotion | D11: Salon Hotel | E11: 0 | F11: 0 | G11: =F11 -> 0 | H11: 0 | I11: =G11-H11 -> 0
B12: 126 | C12: Promotion | D12: Merchandising | E12: 0 | F12: 0 | G12: =F12 -> 0 | H12: 0 | I12: =G12-H12 -> 0
B13: 125 | C13: Promotion | D13: Charlas Conecta | E13: 0 | F13: 0 | G13: =F13 -> 0 | H13: 1318635 | I13: =G13-H13 -> -1318635
B14: 109 | C14: Promotion | D14: Marketing - Pagina WEB Diseño (COP) - Revistas | E14: 0 | F14: 0 | G14: =F14 -> 0 | H14: 0 | I14: =G14-H14 -> 0
B15: 130 | C15: Promotion | D15: Marketing - Mariela Castro | E15: 0 | F15: 4508773 | G15: =F15 -> 4508773 | H15: 4678364 | I15: =G15-H15 -> -169591
B16: 131 | C16: Promotion | D16: Marketing - Pagina WEB (COP) - Marketing Digital | E16: 0 | F16: 0 | G16: =F16 -> 0 | H16: 210238 | I16: =G16-H16 -> -210238
... B21: 136 | C21: Promotion | D21: Asesoria Software - Bastian SITR y SLRP | E21: 11400000 | F21: 11400000 | G21: =F21 -> 11400000 | H21: 13735459 | I21: =G21-H21 -> -2335459
B22: 137 | C22: Promotion | D22: SAM 1,2,3,4,5 | E22: 5000000 | F22: 5000000 | G22: 5000000 | H22: 6416114 | I22: =G22-H22 -> -1416114
B23: 44 | C23: Promotion | D23: Jornadas Técnicas -Evemto ECCE- Eventos extranjero distributech | E23: 0 | F23: 0 | G23: =F23 -> 0 | H23: 0 | I23: =G23-H23 -> 0
B24: 105 | C24: Supplies | D24: Hubspot | E24: 2004000 | F24: 2004000 | G24: =F24 -> 2004000 | H24: 2004000 | I24: =G24-H24 -> 0
B25: 93 | C25: Travel & Transportation | D25: Traslados Área Comercial - Avión y Bus | E25: 7632000 | F25: 5082000 | G25: 5082000 | H25: 12628931 | I25: =G25-H25 -> -7546931
B26: 113 | C26: Travel & Transportation | D26: Viajes Área Comercial - Extranjero | E26: 6000000 | F26: 2500000 | G26: 2500000 | H26: 0 | I26: =G26-H26 -> 2500000
B27: 100 | C27: Travel & Transportation | D27: Comidas Área Comercial - Clientes | E27: 8520000 | F27: 5970000 | G27: 5970000 | H27: 5083471 | I27: =G27-H27 -> 886529
B28: 102 | C28: Travel & Transportation | D28: Rendiciones Vistas Comerc y Tecnica | E28: 2340000 | F28: 2340000 | G28: =F28 -> 2340000 | H28: 981712 | I28: =G28-H28 -> 1358288
B29: 8 | C29: Travel & Transportation | D29: Alojamiento Área Comercial - 24 Estadías en Hoteles | E29: 4800000 | F29: 3300000 | G29: 3300000 | H29: 1172297 | I29: =G29-H29 -> 2127703
E30: =SUM(Presupuesto_Comercial[Presupuesto Inicial]) -> 54382000 | F30: =SUM(Presupuesto_Comercial[Reasignado en Junio]) -> 54382000 | G30: =SUM(Presupuesto_Comercial[Reasignación Final]) -> 54382000 | H30: =SUM(Presupuesto_Comercial[Real a Noviembre]) -> 57798823 | I30: =Presupuesto_Comercial[[#TOTALS],[Reasignado en Junio]]-Presupuesto_Comercial[[#TOTALS],[Real a Noviembre]] -> -3416823
B33: 113 a la 93 | I33: =D67-I25 -> 12910644
B34: pasaje, camioneta, alojamiento
B35: 1 antofa 1 coquimbo 1 chuqui 1 vallenar - 4 sur
B36: 2 días los del norte
B37: 1 semana sur
B39: Antofagasta: | C39: 2 personas 2 días
C40: Vuelo | D40: =465000*2 -> 930000
C41: Alojamiento | D41: =71400*2 -> 142800
C42: Vehículo | D42: =322085/2 -> 161042.5
D43: =SUM(D40:D42) -> 1233842.5
B45: Coquimbo: | C45: 2 personas 2 días
C46: Vuelo | D46: =300000*2 -> 600000
C47: Alojamiento | D47: =54622*2 -> 109244
C48: Vehículo | D48: 221413
D49: =SUM(D46:D48) -> 930657
B51: Vallenar: | C51: 2 personas 2 días
...

Sheet BONOS
A1: BONOS
G2: Simulación
B3: Bono: | C3: 10% de todo lo que supere la Meta Piso | H3: Al 18 de Julio | I3: Proyección 2do Semestre | J3: Total
B4: Meta Piso: | C4: 736000 | D4: Margen bruto | G4: MB a Junio | H4: =('METAS VTAS Y OCS'!G69+'METAS VTAS Y OCS'!G79+'METAS VTAS Y OCS'!G87+'METAS VTAS Y OCS'!G99+'METAS VTAS Y OCS'!G104+'METAS VTAS Y OCS'!G110+'METAS VTAS Y OCS'!G111+'METAS VTAS Y OCS'!G112) -> 449885 | I4: 881000 | J4: =SUM(H4:I4) -> 1330885
G5: Margen Bono | H5: =H4-B8 -> 81885 | I5: =I4-C8 -> 513000 | J5: =SUM(H5:I5) -> 594885
B6: Medición Semestral M$ | G6: Bono | H6: =H5*10% -> 8188.5 | I6: =I5*10% -> 51300 | J6: =SUM(H6:I6) -> 59488.5
B7: 1 | C7: 2
B8: =C4/2 -> 368000 | C8: =B8 -> 368000
B10: Asignación
B11: Franco Travaglini | C11: 0.5 | D11: =(C11*100%)/$F$11 -> 0.53475936 | E11: 0.5 | F11: =C11+C12+C13+C14 -> 0.935 | G11: Franco Travaglini | H11: =C11*$H$6 -> 4094.25 | I11: =$I$6*C11 -> 25650 | J11: =H11+I11 -> 29744.25
B12: Kevin Fuentealba | C12: 0.25 | D12: =(C12*100%)/$F$11 -> 0.26737968 | E12: 0.2 | G12: Kevin Fuentealba | H12: =C12*$H$6 -> 2047.125 | I12: =$I$6*C12 -> 12825 | J12: =H12+I12 -> 14872.125
B13: Bruno Jofré | C13: 0.12 | D13: =(C13*100%)/$F$11 -> 0.12834225 | E13: 0.15 | G13: Bruno Jofré | H13: =C13*$H$6 -> 982.62 | I13: =$I$6*C13 -> 6156 | J13: =H13+I13 -> 7138.62
B14: Francisco Catalán | C14: 0.065 | D14: =(C14*100%)/$F$11 -> 0.069518717 | E14: 0.15 | G14: Francisco Catalán | H14: =C14*$H$6 -> 532.2525 | I14: =$I$6*C14 -> 3334.5 | J14: =H14+I14 -> 3866.7525
B15: Carlos Canelo | C15: 0.065 | G15: Carlos Canelo | H15: =C15*$H$6 -> 532.2525 | I15: =$I$6*C15 -> 3334.5 | J15: =H15+I15 -> 3866.7525
C16: =SUM(C11:C15) -> 1 | H16: =SUM(H11:H15) -> 8188.5 | I16: =SUM(I11:I15) -> 51300 | J16: =H16+I16 -> 59488.5
G18: Con proporcional de Carlos Canelo (Ingreso en Junio):
B19: Franco Travaglini | C19: =C11+D11*$D$23 -> 0.51448307 | G19: Franco Travaglini | H19: =C19*$H$6 -> 4212.8446 | I19: =$I$6*C19 -> 26392.981 | J19: =H19+I19 -> 30605.826 | P19: 2026
B20: Kevin Fuentealba | C20: =C12+D12*$D$23 -> 0.25724153 | G20: Kevin Fuentealba | H20: =C20*$H$6 -> 2106.4223 | I20: =$I$6*C20 -> 13196.491 | J20: =H20+I20 -> 15302.913 | P20: Evaluar el pago trimestral
B21: Bruno Jofré | C21: =C13+D13*$D$23 -> 0.12347594 | G21: Bruno Jofré | H21: =C21*$H$6 -> 1011.0827 | I21: =$I$6*C21 -> 6334.3155 | J21: =H21+I21 -> 7345.3982 | P21: 2027
B22: Francisco Catalán | C22: =C14+D14*$D$23 -> 0.066882799 | G22: Francisco Catalán | H22: =C22*$H$6 -> 547.6698 | I22: =$I$6*C22 -> 3431.0876 | J22: =H22+I22 -> 3978.7574 | P22: Pago mensual
B23: Carlos Canelo | C23: =C15*7/12 -> 0.037916667 | D23: =C15-C23 -> 0.027083333 | G23: Carlos Canelo | H23: =C23*$H$6 -> 310.48062 | I23: =$I$6*C23 -> 1945.125 | J23: =H23+I23 -> 2255.6056 | P23: Añadir bonos totales en EERR 2026
C24: =SUM(C19:C23) -> 1 | H24: =SUM(H19:H23) -> 8188.5 | I24: =SUM(I19:I23) -> 51300 | J24: =H24+I24 -> 59488.5 | P24: Proyección al 2031
M25: Por pagar real
G26: Pago | H26: Julio | I26: Agosto | J26: 46082 | K26: 46113 | L26: Informado | M26: 46082 | N26: 46113 | O26: 46143 | P26: 46174 | Q26: Total
G27: Franco Travaglini | H27: =H19/2 -> 2106.4223 | I27: =H27 -> 2106.4223 | J27: ='METAS VTAS Y OCS'!$G$195*D11/2 -> 8714.9465 | K27: =J27 -> 8714.9465 | L27: =J27+K27 -> 17429.893 | M27: ='METAS VTAS Y OCS'!$G$199*D11/4 -> 5207.8743 | N27: =M27 -> 5207.8743 | O27: =M27 -> 5207.8743 | P27: =M27 -> 5207.8743 | Q27: =M27+N27+O27+P27 -> 20831.497
G28: Kevin Fuentealba | H28: =H20/2 -> 1053.2111 | I28: =H28 -> 1053.2111 | J28: ='METAS VTAS Y OCS'!$G$195*D12/2 -> 4357.4733 | K28: =J28 -> 4357.4733 | L28: =J28+K28 -> 8714.9465 | M28: ='METAS VTAS Y OCS'!$G$199*D12/4 -> 2603.9372 | N28: =M28 -> 2603.9372 | O28: =N28 -> 2603.9372 | P28: =O28 -> 2603.9372 | Q28: =M28+N28+O28+P28 -> 10415.749
G29: Bruno Jofré | H29: =H21 -> 1011.0827 | J29: ='METAS VTAS Y OCS'!$G$195*D13/2 -> 2091.5872 | K29: =J29 -> 2091.5872 | L29: =J29+K29 -> 4183.1743 | M29: ='METAS VTAS Y OCS'!$G$199*D13/2 -> 2499.7797 | N29: =M29 -> 2499.7797 | Q29: =M29+N29+O29+P29 -> 4999.5594
G30: Francisco Catalán | H30: =H22 -> 547.6698 | J30: ='METAS VTAS Y OCS'!$G$195*D14/2 -> 1132.943 | K30: =J30 -> 1132.943 | L30: =J30+K30 -> 2265.8861 | M30: ='METAS VTAS Y OCS'!$G$199*D14/2 -> 1354.0473 | N30: =M30 -> 1354.0473 | Q30: =M30+N30+O30+P30 -> 2708.0947
G31: Carlos Canelo | H31: =H23 -> 310.48062 | J31: ='METAS VTAS Y OCS'!$G$195*D15/2 -> 0 | K31: =J31 -> 0 | L31: =J31+K31 -> 0 | M31: ='METAS VTAS Y OCS'!$G$195*D15/2 -> 0 | N31: =M31 -> 0 | Q31: =M31+N31+O31+P31 -> 0
H32: =SUM(H27:H31) -> 5028.8666 | I32: =SUM(I27:I31) -> 3159.6334 | J32: =SUM(J27:J31) -> 16296.95 | K32: =SUM(K27:K31) -> 16296.95 | L32: =J32+K32 -> 32593.9 | M32: =SUM(M27:M31) -> 11665.638 | N32: =SUM(N27:N31) -> 11665.638 | O32: =SUM(O27:O31) -> 7811.8115 | P32: =SUM(P27:P31) -> 7811.8115
I34: Pagado | M34: =M27/1000 -> 5.2078743 | N34: =N27/1000 -> 5.2078743 | O34: =O27/1000 -> 5.2078743 | P34: =P27/1000 -> 5.2078743 | Q34: =Q27/1000 -> 20.831497
M35: =M28/1000 -> 2.6039372 | N35: =N28/1000 -> 2.6039372 | O35: =O28/1000 -> 2.6039372 | P35: =P28/1000 -> 2.6039372 | Q35: =Q28/1000 -> 10.415749
M36: =M29/1000 -> 2.4997797 | N36: =N29/1000 -> 2.4997797 | O36: =O29/1000 -> 0 | P36: =P29/1000 -> 0 | Q36: =Q29/1000 -> 4.9995594
M37: =M30/1000 -> 1.3540473 | N37: =N30/1000 -> 1.3540473 | O37: =O30/1000 -> 0 | P37: =P30/1000 -> 0 | Q37: =Q30/1000 -> 2.7080947
