Workbook

Sheet Panel
B1: METAS VENTAS Y OCS 2026 MCLP
B2: Fecha actualización | C2: 46210
B4: Normativo | C4: Enero | D4: Febrero | F4: Marzo | G4: Abril | H4: Mayo | I4: Junio | J4: Julio | K4: Agosto | L4: Septiembre | M4: Octubre | N4: Noviembre | O4: Diciembre | P4: Total
B5: Meta acumulada | C5: 0 | D5: =C5+D6 -> 138 | F5: =D5+F6 -> 673 | G5: =F5+G6 -> 736.5 | H5: =G5+H6 -> 771.5 | I5: =H5+I6 -> 1081.1 | J5: =I5+J6 -> 1081.1 | K5: =J5+K6 -> 1081.1 | L5: =K5+L6 -> 2093.1 | M5: =L5+M6 -> 2513.1 | N5: =M5+N6 -> 2533.1 | O5: =N5+O6 -> 2533.1 | P5: =O5 -> 2533.1
B6: Proyección anual | C6: 0 | D6: 138 | F6: 535 | G6: 63.5 | H6: 35 | I6: 309.6 | J6: 0 | K6: 0 | L6: 1012 | M6: 420 | N6: 20 | O6: 0 | P6: =SUM(C6:O6) -> 2533.1
B7: OCs acumuladas | C7: =C8 -> 241.491 | D7: =C7+D8 -> 595.891 | F7: =D7+F8 -> 912.961 | G7: =F7+G8 -> 992.415 | H7: =G7+H8 -> 1482.877 | I7: =H7+I8 -> 1629.222
B8: OCs mensual | C8: =F79+F80+F81+F82+F84+F85+F86 -> 241.491 | D8: =(F89+F90+F92+F93+F94+F95) -> 354.4 | F8: =F97+F98+F100+F101+F102+F103+F104+F105+F106 -> 317.07 | G8: =F119 -> 79.454 | H8: =F121+F122+F124+F125+F126+F127+F129+F131+F132+F133+F134+F130 -> 490.462 | I8: =F137+F138+F139+F141+F143+F145 -> 146.345
B10: SCADAS Y SAC | C10: Enero | D10: Febrero | F10: Marzo | G10: Abril | H10: Mayo | I10: Junio | J10: Julio | K10: Agosto | L10: Septiembre | M10: Octubre | N10: Noviembre | O10: Diciembre | P10: Total
B11: Meta acumulada | C11: 0 | D11: =C11+D12 -> 58 | F11: =D11+F12 -> 133 | G11: =F11+G12 -> 313.8 | H11: =G11+H12 -> 367.5 | I11: =H11+I12 -> 447.5 | J11: =I11+J12 -> 696.5 | K11: =J11+K12 -> 951.5 | L11: =K11+L12 -> 1019 | M11: =L11+M12 -> 1138.5 | N11: =M11+N12 -> 1303.5 | O11: =N11+O12 -> 1303.5 | P11: =O11 -> 1303.5
B12: Proyección anual | C12: 0 | D12: 58 | F12: 75 | G12: 180.8 | H12: 53.7 | I12: 80 | J12: 249 | K12: 255 | L12: 67.5 | M12: 119.5 | N12: 165 | O12: 0 | P12: =SUM(C12:O12) -> 1303.5
B13: OCs acumuladas | C13: =C14 -> 37.98 | D13: =C13+D14 -> 37.98 | F13: =D13+F14 -> 46.256 | G13: =F13+G14 -> 46.256 | H13: =G13+H14 -> 50.039 | I13: =H13+I14 -> 50.039
B14: OCs mensual | C14: =F83 -> 37.98 | D14: 0 | F14: =F99 -> 8.276 | G14: 0 | H14: =F120 -> 3.783 | I14: 0
B16: PAC | C16: Enero | D16: Febrero | F16: Marzo | G16: Abril | H16: Mayo | I16: Junio | J16: Julio | K16: Agosto | L16: Septiembre | M16: Octubre | N16: Noviembre | O16: Diciembre | P16: Total
B17: Meta acumulada | C17: 0 | D17: =C17+D18 -> 498.7 | F17: =D17+F18 -> 569.8 | G17: =F17+G18 -> 591.8 | H17: =G17+H18 -> 749.5 | I17: =H17+I18 -> 766.4 | J17: =I17+J18 -> 766.4 | K17: =J17+K18 -> 766.4 | L17: =K17+L18 -> 1221.4 | M17: =L17+M18 -> 1299.4 | N17: =M17+N18 -> 1326.9 | O17: =N17+O18 -> 1326.9 | P17: =O17 -> 1326.9
B18: Proyección anual | C18: 0 | D18: 498.7 | F18: 71.1 | G18: 22 | H18: 157.7 | I18: 16.9 | J18: 0 | K18: 0 | L18: 455 | M18: 78 | N18: 27.5 | O18: 0 | P18: =SUM(C18:O18) -> 1326.9
B19: OCs acumuladas | C19: =C20 -> 13.339 | D19: =C19+D20 -> 132.639 | F19: =D19+F20 -> 132.639 | G19: =F19+G20 -> 132.639 | H19: =G19+H20 -> 174.218 | I19: =H19+I20 -> 227.078
B20: OCs mensual | C20: =F78+F87 -> 13.339 | D20: =F91 -> 119.3 | F20: 0 | G20: 0 | H20: =F123+F128+F135 -> 41.579 | I20: =F144+F146+F147+F148 -> 52.86
B22: PROCESOS (SISTEMAS Y SOLUCIONES) | C22: Enero | D22: Febrero | F22: Marzo | G22: Abril | H22: Mayo | I22: Junio | J22: Julio | K22: Agosto | L22: Septiembre | M22: Octubre | N22: Noviembre | O22: Diciembre | P22: Total
B23: Meta acumulada | C23: 0 | D23: =C23+D24 -> 0 | F23: =D23+F24 -> 0 | G23: =F23+G24 -> 0 | H23: =G23+H24 -> 0 | I23: =H23+I24 -> 0 | J23: =I23+J24 -> 0 | K23: =J23+K24 -> 150 | L23: =K23+L24 -> 150 | M23: =L23+M24 -> 750 | N23: =M23+N24 -> 900 | O23: =N23+O24 -> 1500 | P23: =O23 -> 1500
B24: Proyección anual | C24: 0 | D24: 0 | F24: 0 | G24: 0 | H24: 0 | I24: 0 | J24: 0 | K24: 150 | L24: 0 | M24: 600 | N24: 150 | O24: 600 | P24: =SUM(C24:O24) -> 1500
B25: OCs acumuladas | C25: 0 | D25: 0 | F25: 0 | G25: 0 | H25: 0 | I25: 0
B26: OCs mensual | C26: 0 | D26: 0 | F26: 0 | G26: 0 | H26: 0
B28: PROCESOS (ÁREA DE EQUIPOS) | C28: Enero | D28: Febrero | F28: Marzo | G28: Abril | H28: Mayo | I28: Junio | J28: Julio | K28: Agosto | L28: Septiembre | M28: Octubre | N28: Noviembre | O28: Diciembre | P28: Total
B29: Meta acumulada | C29: 0 | D29: =C29+D30 -> 0 | F29: =D29+F30 -> 0 | G29: =F29+G30 -> 0 | H29: =G29+H30 -> 0 | I29: =H29+I30 -> 0 | J29: =I29+J30 -> 0 | K29: =J29+K30 -> 0 | L29: =K29+L30 -> 0 | M29: =L29+M30 -> 0 | N29: =M29+N30 -> 0 | O29: =N29+O30 -> 0 | P29: =O29 -> 0
B30: Proyección anual | C30: 0 | D30: 0 | F30: 0 | G30: 0 | H30: 0 | P30: =SUM(C30:O30) -> 0
B31: OCs acumuladas | C31: 0 | D31: 0 | F31: 0 | G31: 0 | H31: 0
B32: OCs mensual | C32: 0 | D32: 0 | F32: 0 | G32: 0 | H32: 0
B49: TOTAL | C49: Enero | D49: Febrero | F49: Marzo | G49: Abril | H49: Mayo | I49: Junio | J49: Julio | K49: Agosto | L49: Septiembre | M49: Octubre | N49: Noviembre | O49: Diciembre | P49: Total
B50: Meta acumulada | C50: =C5+C11+C17+C23 -> 0 | D50: =D5+D11+D17+D23 -> 694.7 | F50: =F5+F11+F17+F23 -> 1375.8 | G50: =G5+G11+G17+G23 -> 1642.1 | H50: =H5+H11+H17+H23 -> 1888.5 | I50: =I5+I11+I17+I23 -> 2295 | J50: =J5+J11+J17+J23 -> 2544 | K50: =K5+K11+K17+K23 -> 2949 | L50: =L5+L11+L17+L23 -> 4483.5 | M50: =M5+M11+M17+M23 -> 5701 | ... O50: =O5+O11+O17+O23 -> 6663.5 | P50: 6664
B51: Proyección anual | C51: =C6+C12+C18+C24 -> 0 | D51: =D6+D12+D18+D24 -> 694.7 | F51: =F6+F12+F18+F24 -> 681.1 | G51: =G6+G12+G18+G24 -> 266.3 | H51: =H6+H12+H18+H24 -> 246.4 | I51: =I6+I12+I18+I24 -> 406.5 | J51: =J6+J12+J18+J24 -> 249 | K51: =K6+K12+K18+K24 -> 405 | L51: =L6+L12+L18+L24 -> 1534.5 | M51: =M6+M12+M18+M24 -> 1217.5 | ... O51: =O6+O12+O18+O24 -> 600
B52: OCs acumuladas | C52: =C7+C13+C19+C25 -> 292.81 | D52: =D7+D13+D19+D25 -> 766.51 | F52: =F7+F13+F19+F25 -> 1091.856 | G52: =G7+G13+G19+G25 -> 1171.31 | H52: =H7+H13+H19+H25 -> 1707.134 | I52: =I7+I13+I19+I25 -> 1906.339 | J52: =J7+J13+J19+J25 -> 0 | K52: =K7+K13+K19+K25 -> 0 | L52: =L7+L13+L19+L25 -> 0 | M52: =M7+M13+M19+M25 -> 0 | ... O52: =O7+O13+O19+O25 -> 0
B53: OCs mensual | C53: =C8+C14+C20+C26 -> 292.81 | D53: =D8+D14+D20+D26 -> 473.7 | F53: =F8+F14+F20+F26 -> 325.346 | G53: =G8+G14+G20+G26 -> 79.454 | H53: =H8+H14+H20+H26 -> 535.824 | I53: =I8+I14+I20+I26 -> 199.205 | J53: =J8+J14+J20+J26 -> 0 | K53: =K8+K14+K20+K26 -> 0 | L53: =L8+L14+L20+L26 -> 0 | M53: =M8+M14+M20+M26 -> 0 | ... O53: =O8+O14+O20+O26 -> 0
B76: Traspasos realizados: | E76: 40300
B77: Cliente | C77: OT | D77: VENTA EN UF | F77: VENTA EN M$ | G77: Costo Bruto M$ | H77: MB M$ | I77: Costo Neto M$ | J77: MN M$ | K77: Línea | L77: Descripcion
B78: Transelec | C78: 5153-03 | D78: 320 | F78: 13.067 | G78: 6.22 | H78: 6.847 | I78: 8.974 | J78: 4.092 | K78: PAC | L78: Integracion señales Quillota y Itahue | Q78: =H78/F78 -> 0.52399173
B79: Grenergy | C79: 5215-00 | D79: 2748 | F79: 109.172 | G79: 73.659 | H79: 35.514 | I79: 84.851 | J79: 24.32 | K79: Normativo | L79: Suministro Unidades de Medicion Sincrofasorial | Q79: =H79/F79 -> 0.32530319
B80: Agrosonda | C80: 5216-00 | D80: 1042 | F80: 41.397 | G80: 24.995 | H80: 16.765 | I80: 30.268 | J80: 11.128 | K80: Normativo | L80: Suministro e implementacion PMU y PDC PFV Planchón | Q80: =H80/F80 -> 0.40498104
B81: Arauco | C81: 5217-00 | D81: 1718 | F81: 69 | G81: 43.593 | H81: 25.54 | I81: 50.733 | J81: 17.518 | K81: Normativo | L81: Implementación de la PMU TG1 y TG3 PCNA (Nueva Aldea) | Q81: =H81/F81 -> 0.37014493
B82: Sigma | C82: 8375-01 | D82: 35.8 | F82: 1.422 | G82: 0.789 | H82: 0.633 | I82: 0.848 | J82: 0.574 | K82: Normativo | L82: Levantamiento y Diagnostico de RTU ABB 560 en instalaciones de ENAEX | Q82: =H82/F82 -> 0.44514768
B83: Colbun | C83: 8387-00 | D83: 956 | F83: 37.98 | G83: 12.605 | H83: 25.864 | I83: 24.537 | J83: 13.442 | K83: SCADA-SAC | L83: Integración PE Totoral a CCR | Q83: =H83/F83 -> 0.68098999
...

Sheet Proyección Q1 (Enero)
A1: Línea | B1: Oportunidad | C1: Cliente | D1: Vendedor | E1: Ingreso esperado | F1: Cierre esperado | G1: Etapa | H1: Probabilidad | I1: Ingreso con % | J1: Resultado Enero
A2: PAC | B2: Transelec - Retrofit de Protecciones | C2: TRANSELEC S A | D2: Kevin Fuentealba | E2: 120 | F2: 46052 | G2: Cierre 70% (Preferencia) | H2: 0.6 | I2: =E2*H2 -> 72 | J2: Se corre a Febrero
A3: Normativo | B3: Electrica Puntilla - Ingeniería Ing. Basica y de Detalle (7 PMUs) | D3: Francisco Catalan | E3: 20 | F3: 46053 | G3: Cierre 90% (Adjudicación Verbal) | H3: 0.9 | I3: =E3*H3 -> 18 | J3: OC
A4: SCADA | B4: Integración de 9 Protecciones al SCADA | C4: Codelco | D4: Franco Travaglini | E4: 10 | F4: 46112 | G4: Cierre 70% (Preferencia) | H4: 0.7 | I4: =E4*H4 -> 7
A5: Normativo | B5: acondicionamiento del SITR mantoverde | C5: MANTOS COPPER S.A. | D5: Francisco Catalan | E5: 25 | F5: 46080 | G5: Cierre 90% (Adjudicación Verbal) | H5: 0.9 | I5: =E5*H5 -> 22.5
A6: Normativo | B6: Codelco Gabriela Mistral - SLRP | D6: Franco Travaglini | E6: 39 | F6: 46112 | G6: Cierre 70% (Preferencia) | H6: 0.7 | I6: =E6*H6 -> 27.3
A7: PAC | B7: Reemplazo SAS Hualpén- Transelec | C7: TRANSELEC S A | D7: Kevin Fuentealba | E7: 736 | F7: 46080 | G7: Cierre 60% (CT Cubierto) | H7: 0.6 | I7: =E7*H7 -> 441.6
A8: Normativo | B8: PMU La Huayca | C8: Saferay | D8: Francisco Catalan | E8: 35 | F8: 46081 | G8: Cierre 60% (CT Cubierto) | H8: 0.6 | I8: =E8*H8 -> 21
A9: Normativo | B9: Visita de levantamiento | C9: Cementos Melon | D9: Francisco Catalan | E9: 3 | F9: 46081 | G9: Cierre 60% (CT Cubierto) | H9: 0.5 | I9: =E9*H9 -> 1.5
A10: Normativo | B10: Suministro e Integración 4 x PMU y 1 x PDC centralizado | C10: Statkraft | D10: Francisco Catalan | E10: 145 | F10: 46112 | G10: Cierre 70% (Preferencia) | H10: 0.5 | I10: =E10*H10 -> 72.5
A11: SCADA | B11: Servicios Reconectadores Fase 1 | C11: Chilquinta | D11: Franco Travaglini | E11: 50 | F11: 46081 | G11: Cierre 90% (Adjudicación Verbal) | H11: 0.9 | I11: =E11*H11 -> 45
A12: Normativo | B12: Implementación 6 PMUs | C12: Inkia | D12: Franco Travaglini | E12: 220 | F12: 46112 | G12: Cierre | H12: 0.5 | I12: =E12*H12 -> 110
A13: Normativo | B13: 5 x PMU de Sonnedix + PDC | C13: Sonnedix PMU | D13: Franco Travaglini | E13: 180 | F13: 46112 | G13: Cierre 70% (Preferencia) | H13: 0.7 | I13: =E13*H13 -> 126
A14: Normativo | B14: PMU - Eletrans | C14: Eletrans | D14: Franco Travaglini | E14: 86 | F14: 46112 | G14: Cierre 70% (Preferencia) | H14: 0.7 | I14: =E14*H14 -> 60.2
A15: Normativo | B15: PMU Campo lindo y PE San Matias | C15: AES | D15: Francisco Catalan | E15: 75 | F15: 46112 | G15: Cierre 90% (Adjudicación Verbal) | H15: 0.9 | I15: =E15*H15 -> 67.5
A16: Normativo | B16: Suministro 3 PMU TER - Esperanza | C16: Enorchile S.A. | D16: Francisco Catalan | E16: 73 | F16: 46112 | G16: Cierre | H16: 0.5 | I16: =E16*H16 -> 36.5
A17: Normativo | B17: Central Huasco (3 PMU) | D17: Franco Travaglini | E17: 95 | F17: 46112 | G17: Cierre 70% (Preferencia) | H17: 0.7 | I17: =E17*H17 -> 66.5
A18: Normativo | B18: PMU Mantos Blancos | C18: Diego Navarrete Lucero | D18: Kevin Fuentealba | E18: 70 | F18: 46112 | G18: Cierre | H18: 0.5 | I18: =E18*H18 -> 35
A19: SCADA | B19: Retrofit Protecciones y SCADA La Huayca | C19: Enlight | D19: Franco Travaglini | E19: 100 | F19: 46112 | G19: Cierre | H19: 0.3 | I19: =E19*H19 -> 30
A20: PAC | B20: Guacolda - Eficiencia Energetica | D20: Kevin Fuentealba | E20: 55 | F20: 46112 | G20: Cierre | H20: 0.5 | I20: =E20*H20 -> 27.5
G22: PROYECCIÓN INICIAL | H22: Enero | I22: =SUM(I2:I3) -> 90 | J22: 292
A23: Normativo | B23: Tinguiririca | H23: Febrero | I23: =SUM(I4:I11) -> 638.4
H24: Marzo | I24: =SUM(I12:I20) -> 559.2
H25: Total | I25: =SUM(I22:I24) -> 1287.6

Sheet Proyección Q1 (Febrero)
A1: Línea | B1: Oportunidad | C1: Cliente | D1: Vendedor | E1: Ingreso esperado | F1: Cierre esperado | G1: Etapa | H1: Probabilidad | I1: Ingreso con % | J1: Resultado Febrero | M1: Marzo | N1: Abril | O1: Mayo | P1: Junio | Q1: Julio | R1: Agosto | S1: Septiembre | T1: Octubre | U1: Noviembre | V1: Diciembre
A2: PAC | B2: Transelec - Retrofit de Protecciones | C2: TRANSELEC S A | D2: Kevin Fuentealba | E2: 120 | F2: 46066 | G2: Cierre 90% (Adjudicación Verbal) | H2: 0.9 | I2: =E2*H2 -> 108 | J2: OC
A3: SCADA | B3: Drivers Mantos Blancos | C3: MANTOS COPPER S.A. | D3: Franco Travaglini | E3: 12 | F3: 46079 | G3: Cierre | H3: 0.5 | I3: =E3*H3 -> 6 | J3: Se corre a Marzo
A4: PAC | B4: Reemplazo SAS Hualpén- Transelec | C4: TRANSELEC S A | D4: Kevin Fuentealba | E4: 736 | F4: 46080 | G4: Cierre 60% (CT Cubierto) | H4: 0.6 | I4: =E4*H4 -> 441.6 | J4: Perdido
A5: PAC | B5: Chilquinta - Suministro Relé NR SE Damascal | C5: Chilquinta | D5: Kevin Fuentealba | E5: 15 | F5: 46080 | G5: Cierre 60% (CT Cubierto) | H5: 0.6 | I5: =E5*H5 -> 9 | J5: Se corre a Marzo
A6: Normativo | B6: Visita de levantamiento | C6: Agrosuper | D6: Bruno Jofré | E6: 3 | F6: 46080 | G6: Cierre | H6: 0.9 | I6: =E6*H6 -> 2.7 | J6: OC
A7: Normativo | B7: Acondicionamiento del SITR | C7: Mantoverde | D7: Francisco Catalan | E7: 25 | F7: 46080 | G7: Cierre | H7: 1 | I7: =E7*H7 -> 25 | J7: OC
A8: Normativo | B8: Implementación 2 PMU | C8: Pacific Hydro | D8: Bruno Jofré | E8: 50 | F8: 46080 | G8: Cierre | H8: 1 | I8: =E8*H8 -> 50 | J8: OC
A9: Normativo | B9: Implementación 2 PMU | C9: Tinguiririca | D9: Bruno Jofré | E9: 91 | F9: 46080 | G9: Cierre | H9: 1 | I9: =E9*H9 -> 91 | J9: OC
A10: Normativo | B10: Visita de levantamiento | C10: Cementos Melon | D10: Francisco Catalan | E10: 3 | F10: 46081 | G10: Cierre 60% (CT Cubierto) | H10: 0.5 | I10: =E10*H10 -> 1.5 | J10: Sigue en Febrero
A11: PAC | B11: Trabajos adicionales Diego de Almagro | C11: Chilquinta | D11: Kevin Fuentealba | E11: 30 | F11: 46081 | G11: Cierre | H11: 1 | I11: =E11*H11 -> 30 | J11: Se corre a Marzo
A12: Normativo | B12: PMU La Huayca | C12: Saferay | D12: Francisco Catalan | E12: 35 | F12: 46112 | G12: Cierre 60% (CT Cubierto) | H12: 0.6 | I12: =E12*H12 -> 21
A13: Normativo | B13: Implementación 6 PMUs | C13: Inkia | D13: Franco Travaglini | E13: 220 | F13: 46112 | G13: Cierre | H13: 0.5 | I13: =E13*H13 -> 110
A14: Normativo | B14: 5 x PMU de Sonnedix + PDC | C14: Sonnedix PMU | D14: Franco Travaglini | E14: 180 | F14: 46112 | G14: Cierre 70% (Preferencia) | H14: 0.7 | I14: =E14*H14 -> 126
A15: Normativo | B15: PMU - Eletrans | C15: Eletrans | D15: Franco Travaglini | E15: 86 | F15: 46112 | G15: Cierre 70% (Preferencia) | H15: 0.7 | I15: =E15*H15 -> 60.2
A16: Normativo | B16: PMU Campo lindo y PE San Matias | C16: AES | D16: Francisco Catalan | E16: 75 | F16: 46112 | G16: Cierre 90% (Adjudicación Verbal) | H16: 0.9 | I16: =E16*H16 -> 67.5
A17: Normativo | B17: Suministro e Integración 4 x PMU y 1 x PDC centralizado | C17: Statkraft | D17: Francisco Catalan | E17: 145 | F17: 46112 | G17: Cierre 70% (Preferencia) | H17: 0.5 | I17: =E17*H17 -> 72.5
A18: Normativo | B18: Suministro 3 PMU TER - Esperanza | C18: Enorchile S.A. | D18: Francisco Catalan | E18: 73 | F18: 46112 | G18: Cierre | H18: 0.5 | I18: =E18*H18 -> 36.5
A19: Normativo | B19: Codelco Gabriela Mistral - SLRP | C19: Codelco | D19: Franco Travaglini | E19: 39 | F19: 46112 | G19: Cierre 70% (Preferencia) | H19: 0.7 | I19: =E19*H19 -> 27.3
A20: Normativo | B20: Central Huasco y Guacolda (3 PMU) + 5 integraciones | C20: Guacolda | D20: Franco Travaglini | E20: 100 | F20: 46112 | G20: Cierre 70% (Preferencia) | H20: 0.7 | I20: =E20*H20 -> 70
A21: Normativo | B21: PMU Mantos Blancos | C21: Diego Navarrete Lucero | D21: Kevin Fuentealba | E21: 70 | F21: 46112 | G21: Cierre | H21: 0.5 | I21: =E21*H21 -> 35
A22: Normativo | B22: Modernización Servidores PDC | C22: TRANSELEC S A | D22: Franco Travaglini | E22: 206 | F22: 46112 | G22: Cierre | H22: 0.9 | I22: =E22*H22 -> 185.4
A23: SCADA | B23: Integración de 9 Protecciones al SCADA | C23: Codelco | D23: Franco Travaglini | E23: 10 | F23: 46112 | G23: Cierre 70% (Preferencia) | H23: 0.7 | I23: =E23*H23 -> 7
... A28: PAC | B28: Servicios Reconectadores Fase 1 | C28: Chilquinta Distribución | D28: Kevin Fuentealba | E28: 50 | F28: 46112 | G28: Cierre 90% (Adjudicación Verbal) | H28: 0.9 | I28: =E28*H28 -> 45
M29: =SUM(M2:M28) -> 0 | N29: =SUM(N2:N28) -> 0 | O29: =SUM(O2:O28) -> 0 | P29: =SUM(P2:P28) -> 0 | Q29: =SUM(Q2:Q28) -> 0 | R29: =SUM(R2:R28) -> 0 | S29: =SUM(S2:S28) -> 0 | T29: =SUM(T2:T28) -> 0 | ... V29: =SUM(V2:V28) -> 0
G30: PROYECCIÓN ACTUALIZADA AL CIERRE DE ENERO | H30: Enero | I30: ='Proyección Q1 (Enero)'!J22 -> 292
H31: Febrero | I31: =SUM(I2:I11) -> 764.8 | J31: =Panel!F96 -> 473.7 | K31: =J31-I31 -> -291.1
H32: Marzo | I32: =SUM(I12:I28) -> 915.4
H33: Total | I33: =SUM(I30:I32) -> 1972.2

Sheet Proyección Q1 (Marzo)
A1: Línea | B1: Oportunidad | C1: Cliente | D1: Vendedor | E1: Ingreso esperado | F1: Cierre esperado | G1: Etapa | H1: Probabilidad | I1: Ingreso con % | J1: Resultado Marzo | N1: Mayo | O1: Junio | P1: Julio | Q1: Agosto | R1: Septiembre | S1: Octubre | T1: Noviembre | U1: Diciembre
A2: Normativo | B2: Suministro e Integración 4 x PMU y 1 x PDC centralizado | C2: Statkraft | D2: Francisco Catalan | E2: 145 | F2: 46112 | G2: Cierre 70% (Preferencia) | H2: 0.5 | I2: =E2*H2 -> 72.5 | J2: OC | N2: =I2*20% -> 14.5 | O2: =I2*25% -> 18.125 | R2: =I2*50% -> 36.25 | S2: =I2*5% -> 3.625
D3: Francisco Catalan | Q3: =H2*20.7 -> 10.35 | R3: =H2*3 -> 1.5 | S3: =H2*4.3 -> 2.15 | T3: =H2*4.5 -> 2.25
A4: Normativo | B4: PMU La Huayca | C4: Enlight Investments Spa | D4: Francisco Catalan | E4: 35 | F4: 46094 | G4: Cierre 60% (CT Cubierto) | H4: 0.6 | I4: =E4*H4 -> 21 | J4: OC
A5: Normativo | B5: Integración PMU Arrayan a Maitencillo | C5: Sonnedix Chile Holding S.p.A. | D5: Bruno Jofré | E5: 8 | F5: 46112 | G5: Cierre | H5: 0.3 | I5: =E5*H5 -> 2.4 | J5: Se corre a Abril
A6: Normativo | B6: Ampliación PDC 3 Licencias | C6: Acciona Energia Chile S.p.A. | D6: Franco Travaglini | E6: 10 | F6: 46112 | G6: Cierre | H6: 0.7 | I6: =E6*H6 -> 7 | J6: Se corre a Abril
A7: Normativo | B7: PDC SAESA | C7: Sociedad Austral de Electricidad S.A. | D7: Franco Travaglini | E7: 50 | F7: 46112 | G7: Cierre | H7: 0.5 | I7: =E7*H7 -> 25 | J7: Se corre a Abril
A8: Normativo | B8: Mtto PDCE 2026 | C8: CELEO REDES CHILE LIMITADA | D8: Franco Travaglini | E8: 64 | F8: 46112 | G8: Cierre 70% (Preferencia) | H8: 0.9 | I8: =E8*H8 -> 57.6 | J8: OC | N8: =I8*50% -> 28.8 | S8: =N8 -> 28.8
D9: Franco Travaglini
A10: Normativo | B10: IO - Licencias PDC | C10: IO | D10: Kevin Fuentealba | E10: 12 | F10: 46112 | G10: Cierre | H10: 0.9 | I10: =E10*H10 -> 10.8 | J10: OC | N10: =I10 -> 10.8
D11: Kevin Fuentealba | P11: =H10*10 -> 9
A12: Normativo | B12: Modernización Servidores PDC | C12: TRANSELEC S A | D12: Franco Travaglini | E12: 206 | F12: 46112 | G12: Cierre 60% (CT Cubierto) | H12: 0.9 | I12: =E12*H12 -> 185.4 | J12: OC | N12: =I12*15%*49% -> 13.6269 | O12: =I12*15%*49% -> 13.6269 | Q12: =I12*15%*49%+I12*51% -> 108.1809 | R12: =I12*20%*49% -> 18.1692 | S12: =I12*20%*49% -> 18.1692 | T12: =I12*10%*49% -> 9.0846 | U12: =I12*5%*49% -> 4.5423
D13: Franco Travaglini | O13: =H12*5.2 -> 4.68 | R13: =H12*78.4 -> 70.56 | S13: =O13 -> 4.68 | T13: =O13 -> 4.68 | U13: =O13 -> 4.68
A14: Scada | B14: Scada se magallanes | C14: ENAP | D14: Franco Travaglini | E14: 70 | F14: 46112 | G14: Cierre 60% (CT Cubierto) | H14: 0.6 | I14: =E14*H14 -> 42 | J14: ?
A15: PAC | B15: Chilquinta - Trabajos adicionales RTU SE DDA | C15: Chilquinta | D15: Kevin Fuentealba | E15: 31 | F15: 46112 | G15: Cierre 70% (Preferencia) | H15: 0.9 | I15: =E15*H15 -> 27.9 | J15: Se corre a Abril | N15: =I15/5 -> 5.58 | O15: =N15 -> 5.58 | P15: =O15 -> 5.58 | Q15: =P15 -> 5.58 | R15: =Q15 -> 5.58
D16: Kevin Fuentealba
A17: PAC | B17: Chilquinta - Suministro Relé NR SE Damascal | C17: Chilquinta | D17: Kevin Fuentealba | E17: 40 | F17: 46112 | G17: Cierre 60% (CT Cubierto) | H17: 0.6 | I17: =E17*H17 -> 24 | J17: Se corre a Mayo | N17: =I17*20% -> 4.8 | O17: =N17 -> 4.8 | P17: =O17 -> 4.8 | Q17: =I17*40% -> 9.6
D18: Kevin Fuentealba | Q18: =H17*2 -> 1.2 | R18: =H17*9.6 -> 5.76
A19: PAC | B19: Sigma & Enaex - Retrofit de RTU | C19: Sigma | D19: Kevin Fuentealba | E19: 60 | F19: 46112 | G19: Cierre 60% (CT Cubierto) | H19: 0.6 | I19: =E19*H19 -> 36 | J19: Se corre a Mayo | N19: =I19*20%*73% -> 5.256 | O19: =I19*20%*73%+I19*27% -> 14.976 | P19: =I19*20%*73% -> 5.256 | Q19: =I19*35%*73% -> 9.198 | R19: =I19*5%*73% -> 1.314
D20: Kevin Fuentealba | O20: =H19*0.6 -> 0.36 | Q20: =H19*12.4 -> 7.44
A21: PAC | B21: Transelec - Repro 2026 | C21: TRANSELEC S A | D21: Kevin Fuentealba | E21: 40 | F21: 46112 | G21: Cierre | H21: 0.1 | I21: =E21*H21 -> 4 | J21: Cancelado
D22: Kevin Fuentealba
A23: PAC | B23: Retrofit Protecciones La Huayca | C23: Enlight Investments Spa | D23: Kevin Fuentealba | E23: 100 | F23: 46112 | G23: Cierre | H23: 0.3 | I23: =E23*H23 -> 30 | J23: Se corre a Junio | M23: Presupuestario
D24: Kevin Fuentealba
A25: PAC | B25: TECK - Capacitación de protecciones | C25: Teck | D25: Kevin Fuentealba | E25: 10 | F25: 46112 | G25: Cierre | H25: 0.3 | I25: =E25*H25 -> 3 | J25: Se corre a Sept | O25: =I25 -> 3
D26: Kevin Fuentealba | O26: =H25*9 -> 2.7
A27: PAC | B27: Servicios Reconectadores Fase 1 | C27: Chilquinta Distribucion S.A. | D27: Kevin Fuentealba | E27: 30 | F27: 46112 | G27: Cierre 90% (Adjudicación Verbal) | H27: 0.9 | I27: =E27*H27 -> 27 | J27: Se corre a Abril | N27: =I27*20% -> 5.4 | O27: =I27*15% -> 4.05 | P27: =I27*20% -> 5.4 | S27: =I27*10% -> 2.7 | T27: =I27*30% -> 8.1 | U27: =I27*5% -> 1.35
D28: Kevin Fuentealba | O28: =H27*1.5 -> 1.35 | P28: =H27*2.8 -> 2.52 | R28: =O28 -> 1.35 | S28: =R28 -> 1.35 | T28: =S28 -> 1.35
G30: PROYECCIÓN ACTUALIZADA AL CIERRE DE MARZO | H30: Enero | I30: 292 | J30: =I30 -> 292 | M30: Ingresos | N30: =(N2+N4+N5+N6+N7+N8+N10+N12+N14+N15+N17+N19+N21+N23+N25+N27)*1000000 -> 88762900 | O30: =(O2+O4+O5+O6+O7+O8+O10+O12+O14+O15+O17+O19+O21+O23+O25+O27)*1000000 -> 64157900 | P30: =(P2+P4+P5+P6+P7+P8+P10+P12+P14+P15+P17+P19+P21+P23+P25+P27)*1000000 -> 21036000 | Q30: =(Q2+Q4+Q5+Q6+Q7+Q8+Q10+Q12+Q14+Q15+Q17+Q19+Q21+Q23+Q25+Q27)*1000000 -> 1.325589e+08 | R30: =(R2+R4+R5+R6+R7+R8+R10+R12+R14+R15+R17+R19+R21+R23+R25+R27)*1000000 -> 61313200 | S30: =(S2+S4+S5+S6+S7+S8+S10+S12+S14+S15+S17+S19+S21+S23+S25+S27)*1000000 -> 53294200 | T30: =(T2+T4+T5+T6+T7+T8+T10+T12+T14+T15+T17+T19+T21+T23+T25+T27)*1000000 -> 17184600 | U30: =(U2+U4+U5+U6+U7+U8+U10+U12+U14+U15+U17+U19+U21+U23+U25+U27)*1000000 -> 5892300
H31: Febrero | I31: ='Proyección Q1 (Febrero)'!J31 -> 473.7 | J31: =I31 -> 473.7 | M31: Egresos | N31: =(N3+N9+N11+N13+N16+N18+N20+N22+N24+N26+N28)*1000000 -> 0 | O31: =(O3+O9+O11+O13+O16+O18+O20+O22+O24+O26+O28)*1000000 -> 9090000 | P31: =(P3+P9+P11+P13+P16+P18+P20+P22+P24+P26+P28)*1000000 -> 11520000 | Q31: =(Q3+Q9+Q11+Q13+Q16+Q18+Q20+Q22+Q24+Q26+Q28)*1000000 -> 18990000 | R31: =(R3+R9+R11+R13+R16+R18+R20+R22+R24+R26+R28)*1000000 -> 79170000 | S31: =(S3+S9+S11+S13+S16+S18+S20+S22+S24+S26+S28)*1000000 -> 8180000 | T31: =(T3+T9+T11+T13+T16+T18+T20+T22+T24+T26+T28)*1000000 -> 8280000 | U31: =(U3+U9+U11+U13+U16+U18+U20+U22+U24+U26+U28)*1000000 -> 4680000
H32: Marzo | I32: =SUM(I2:I27) -> 575.6 | J32: =Panel!F107+K4+K8+K12 -> 325.346 | K32: =J32-I32 -> -250.254
H33: Total | I33: =SUM(I30:I32) -> 1341.3 | J33: =SUM(J30:J32) -> 1091.046
G35: Q1 | I35: Proyección Inicial | J35: Resultado
I36: ='Proyección Q1 (Enero)'!I25 -> 1287.6 | J36: =J33 -> 1091.046 | K36: =J36-I36 -> -196.554
A40: Normativo | B40: PMU | C40: Gas sur | D40: Bruno Jofré
A42: Normativo | B42: Ingeniería para implementación de 33 PMU | C42: Colbún | D42: Francisco Catalan | E42: 89 | F42: Abril | G42: Cotización | H42: 0.6 | I42: =E42*H42 -> 53.4 | O42: =I42*20% -> 10.68 | R42: =I42*40% -> 21.36 | U42: =I42*40% -> 21.36
P43: =H42*5 -> 3 | Q43: =P43 -> 3
A44: Normativo | B44: PMU | C44: Barrick | D44: Bruno Jofré | E44: 50 | F44: Mayo | G44: Cotización | H44: 0.5 | I44: =E44*H44 -> 25 | P44: =I44*20% -> 5 | Q44: =I44*25% -> 6.25 | T44: =I44*50% -> 12.5 | U44: =I44*5% -> 1.25
Q45: =0.9*H44 -> 0.45 | T45: =H44*15 -> 7.5 | U45: =H44*13 -> 6.5
A46: Equipos | C46: CPP | D46: Alfonso Calderón | E46: 254 | F46: Abril | G46: Cotización | H46: 0.5 | I46: =E46*H46 -> 127 | O46: =I46*30% -> 38.1 | P46: =(I46-O46)/3 -> 29.633333 | Q46: =P46 -> 29.633333 | R46: =Q46 -> 29.633333
...

Sheet Proyección Q2 (Abril)
A1: Línea | B1: Oportunidad | C1: Cliente | D1: Vendedor | E1: Ingreso esperado | F1: Cierre esperado | G1: Etapa | H1: Probabilidad | I1: Ingreso con % | K1: Resultado Abril | M1: 0 | N1: Junio | O1: Julio | P1: Agosto | Q1: Septiembre | R1: Octubre | S1: Noviembre | T1: Diciembre
A2: Normativo | B2: implementación PMU | C2: Grupo Saesa | D2: Bruno Jofré | E2: 300 | F2: 46118 | G2: Cierre | H2: 0.6 | I2: =E2*H2 -> 180 | K2: Se corre a Mayo
A4: Normativo | B4: 2 x EDAG + 2 x PMU | C4: Southenergy Spa | D4: Bruno Jofré | E4: 120 | F4: 46129 | G4: Cotización | H4: 0.3
A6: SCADA | B6: SCADA Nova - SE | C6: ENAP | D6: Franco Travaglini | E6: 70 | F6: 46129 | G6: Cotización | H6: 0.5 | I6: =E6*H6*M1 -> 0 | N6: =I6/5 -> 0 | O6: =$N$6 -> 0 | P6: =$N$6 -> 0 | Q6: =$N$6 -> 0 | R6: =$N$6 -> 0
O7: =2.4*H6 -> 1.2 | P7: =8.5*H6 -> 4.25 | Q7: =H6*33 -> 16.5 | R7: =H6*4.9 -> 2.45
A8: Normativo | B8: Suministro Licencias PDC | C8: AES ANDES S.A. | D8: Franco Travaglini | E8: 19 | F8: 46142 | G8: Cotización | H8: 0.9
A10: Normativo | B10: Los Cururos implementacion de PMU | C10: AES ANDES S.A. | D10: Franco Travaglini | E10: 12 | F10: 46142 | G10: Cierre 70% (Preferencia) | H10: 0.7 | I10: =E10*H10 -> 8.4 | K10: OC
A12: Normativo | B12: Ingeniería 33 PMUs | C12: Colbun | D12: Francisco Catalan | E12: 100 | F12: 46142 | G12: Cierre 70% (Preferencia) | H12: 0.7 | I12: =E12*H12 -> 70 | K12: OC | L12: Falta traspaso | N12: =I12*20% -> 14 | Q12: =I12*40% -> 28 | T12: =I12*40% -> 28
O13: =3.5*H12 -> 2.45 | P13: =3.5*H12 -> 2.45
A14: Normativo | B14: PMU Santiago Solar | C14: EDF en Chile Holding SpA | D14: Bruno Jofré | E14: 27 | F14: 46142 | G14: Cotización | H14: 0.3
A16: Normativo | B16: Ampliación PDC 3 Licencias | C16: Acciona Energia Chile S.p.A. | D16: Franco Travaglini | E16: 10 | F16: 46142 | G16: Cierre 70% (Preferencia) | H16: 0.7 | I16: =E16*H16 -> 7 | K16: Se corre a Mayo
A18: Normativo | B18: PDC SAESA | C18: Sociedad Austral de Electricidad S.A. | D18: Franco Travaglini | E18: 50 | F18: 46142 | G18: Cierre 90% (Adjudicación Verbal) | H18: 0.9 | I18: =E18*H18 -> 45 | K18: Se corre a Mayo
A20: Normativo | B20: Mtto PDCE 2026 | C20: TRANSELEC S A | D20: Franco Travaglini | E20: 50 | F20: 46142 | G20: Cotización | H20: 0.7 | N20: =E20*H20/2 -> 17.5 | R20: =N20 -> 17.5
A22: Normativo | B22: EDAGxCE Conejo | C22: Sonnedix Chile Holding S.p.A. | D22: Bruno Jofré | E22: 25 | F22: 46142 | G22: Cotización | H22: 0.15
A24: Normativo | B24: Adicionales - montaje switch Ancud | C24: TRANSELEC S A | D24: Franco Travaglini | E24: 2 | F24: 46142 | G24: Cierre 70% (Preferencia) | H24: 0.7 | I24: =E24*H24 -> 1.4 | K24: Se corre a Noviembre
A26: Normativo | B26: SITR Linea 7 | C26: EMPRESA DE TRANSPORTES DE PASAJEROS METRO S.A. | D26: Franco Travaglini | E26: 22 | F26: 46142 | G26: Cierre | H26: 0.5 | I26: =E26*H26 -> 11 | K26: Se corre a Junio
A28: Normativo | B28: SLRP - Centralizado | C28: AES ANDES S.A | D28: Franco Travaglini | E28: 85 | F28: 46142 | G28: Cierre | H28: 0.5 | I28: =E28*H28 -> 42.5 | K28: Se corre a Mayo | N28: =I28*20% -> 8.5 | P28: =I28*25% -> 10.625 | R28: =I28*15% -> 6.375 | S28: =I28*10% -> 4.25 | T28: =I28*15% -> 6.375
P29: =5*H28 -> 2.5 | T29: =25*H28 -> 12.5
A30: SCADA | B30: Drivers Mantos Blancos | C30: MANTOS COPPER S.A. | D30: Franco Travaglini | E30: 12 | F30: 46142 | G30: Cierre | H30: 0.5 | I30: =E30*H30 -> 6 | K30: OC | L30: Falta traspaso
A32: PAC | B32: Chilquinta - Trabajos adicionales RTU SE DDA | C32: Chilquinta Transmisión S.A. | D32: Kevin Fuentealba | E32: 31 | F32: 46142 | G32: Cierre 90% (Adjudicación Verbal) | H32: 0.9 | I32: =E32*H32 -> 27.9 | K32: Falta traspaso
A34: PAC | B34: Dashboard de integración Medidores | C34: AES ANDES S.A. | D34: Franco Travaglini | E34: 3 | F34: 46142 | G34: Cierre | H34: 0.6 | I34: =E34*H34 -> 1.8 | K34: ? | L34: No aparece en embudo
A36: PAC | B36: Servicios Reconectadores Fase 1 | C36: Chilquinta Distribucion S.A. | D36: Kevin Fuentealba | E36: 40 | F36: 46142 | G36: Cierre 90% (Adjudicación Verbal) | H36: 0.9 | I36: =E36*H36 -> 36 | K36: Se corre a Mayo
A38: PAC | B38: Chilquinta - Suministro Relé NR SE Damascal | D38: Kevin Fuentealba | E38: 35 | F38: 46157 | G38: Cierre 90% (Adjudicación Verbal) | H38: 0.7 | I38: =E38*H38 -> 24.5
A40: Normativo | B40: SLRP y PDC Centro de Control | C40: Grenergy | D40: Franco Travaglini | E40: 250 | F40: 46170 | G40: Posicionamiento | H40: 0.5
A42: Normativo | B42: Implementación 2 PMUs | C42: X-elio | D42: Bruno Jofré | E42: 60 | F42: 46171 | G42: Cierre 60% (CT Cubierto) | H42: 0.7 | I42: =E42*H42 -> 42
A44: Normativo | B44: Implementación PMU | C44: Eletrans III S.A | D44: Kevin Fuentealba | E44: 80 | F44: 46171 | G44: Cotización | H44: 0.6 | P44: =E44*H44*20% -> 9.6 | Q44: =E44*H44*25% -> 12 | T44: =E44*H44*50% -> 24
O45: =H44*1.5 -> 0.9 | R45: =H44*2.5 -> 1.5 | S45: =H44*1.4 -> 0.84 | T45: =H44*23 -> 13.8
A46: Normativo | B46: Implementacion PDC | C46: ENORCHILE S.A. | D46: Bruno Jofré | E46: 70 | F46: 46171 | G46: Cotización | H46: 0.5
A48: Normativo | B48: Guacolda - Analisis y medción de calidad de energía | D48: Kevin Fuentealba | E48: 20 | F48: 46171 | G48: Cotización | H48: 0.6
A50: Normativo | B50: PMU Campo lindo y PE San Matias | C50: AES ANDES S.A. | D50: Francisco Catalan | E50: 75 | F50: 46171 | G50: Cierre | H50: 0.9 | I50: =E50*H50 -> 67.5 | J50: falta flujo
A52: Normativo | B52: Suministro e Integración 4 x PMU y 1 x PDC centralizado | C52: Statkraft | D52: Francisco Catalan | E52: 145 | F52: 46171 | G52: Cierre 70% (Preferencia) | H52: 0.5 | I52: =E52*H52 -> 72.5 | J52: falta flujo
A54: Normativo | B54: PMU Zona Centro | C54: TRANSELEC S A | D54: Franco Travaglini | E54: 160 | F54: 46171 | G54: Cotización | H54: 0.7 | Q54: =E54*H54*10% -> 11.2
P55: =1.3*H54 -> 0.91 | Q55: =0.4*H54 -> 0.28 | T55: =9.3*H54 -> 6.51
A56: Normativo | B56: Suministro e implementación PMU | C56: Minera American Barrick Ltda. | D56: Bruno Jofré | E56: 60 | F56: 46171 | G56: Cotización | H56: 0.5
A58: Normativo | B58: Edaltec - Implementación /Suministro PMU - Licencia PDC | D58: Kevin Fuentealba | E58: 30 | F58: 46171 | G58: Cierre | H58: 0.05 | I58: =E58*H58 -> 1.5
A60: Normativo | B60: Codelco Gabriela Mistral - SLRP | C60: Codelco Gabriela Mistral | D60: Franco Travaglini | E60: 39 | F60: 46171 | G60: Cierre 70% (Preferencia) | H60: 0.7 | I60: =E60*H60 -> 27.3
A62: Normativo | B62: Contrato Marco 15 PMU | C62: Chilquinta Transmisión S.A. | D62: Franco Travaglini | E62: 300 | F62: 46171 | G62: Cotización | H62: 0.6
A64: Normativo | B64: 2 x PMU Central Trineo y Maitencillo | C64: Siete Energía | D64: Franco Travaglini | E64: 70 | F64: 46171 | G64: Cierre | H64: 0.5 | I64: =E64*H64 -> 35
A66: Normativo | B66: SITR ENAEX - VERTICE CONSULTORES SPA | C66: SIGMA ENERGÍA SPA | D66: Bruno Jofré | E66: 21 | F66: 46171 | G66: Cierre | H66: 0.25 | I66: =E66*H66 -> 5.25
A68: Normativo | B68: PMU Mantos Blancos | C68: Mantos Cooper | D68: Kevin Fuentealba | E68: 70 | F68: 46171 | G68: Cierre | H68: 0.5 | I68: =E68*H68 -> 35
...

Sheet Proyección Q2 (Mayo)
A1: Línea | B1: Oportunidad | C1: Cliente | D1: Vendedor | E1: Ingreso esperado | F1: Cierre esperado | G1: Etapa | H1: Probabilidad | I1: Ingreso con % | K1: Resultado Mayo | M1: 0 | N1: Julio | O1: Agosto | P1: Septiembre | Q1: Octubre | R1: Noviembre | S1: Diciembre | T1: 46388
A2: Normativo | B2: 10 PMU Zona Cordillera | C2: AES ANDES S.A. | D2: Franco Travaglini | E2: 120 | F2: 46150 | G2: Cierre 90% (Adjudicación Verbal) | H2: 0.9 | I2: =E2*H2 -> 108 | K2: OC
I3: l
A4: Normativo | B4: 2 PMU | C4: Consorcio Santa Marta S.A. | D4: Francisco Catalan | E4: 55 | F4: 46157 | G4: Cierre | H4: 0.1 | I4: =E4*H4 -> 5.5 | K4: Se corre a Agosto | N4: =I4*20% -> 1.1 | O4: =I4*10% -> 0.55 | P4: =I4*20% -> 1.1 | Q4: =I4*25% -> 1.375 | R4: =I4*20% -> 1.1 | S4: =I4*5% -> 0.275
O5: =0.1*H4 -> 0.01 | Q5: =2.3*H4 -> 0.23 | R5: =H4*10 -> 1 | S5: =H4*6.2 -> 0.62
A6: Normativo | B6: PDC SAESA | C6: Sociedad Austral de Electricidad S.A. | D6: Franco Travaglini | E6: 70 | F6: 46157 | G6: Cierre 90% (Adjudicación Verbal) | H6: 0.9 | I6: =E6*H6 -> 63 | K6: OC | N6: =18%*H6*I6*20% -> 2.0412 | O6: =18%*H6*I6*10%+27%*H6*I6 -> 16.3296 | P6: =18%*H6*I6*50%+55%*H6*I6 -> 36.288 | Q6: =18%*H6*I6*20% -> 2.0412
I7: l | P7: =18*H6 -> 16.2 | Q7: =0.5*H6 -> 0.45 | R7: =33.6*H6 -> 30.24
A8: Normativo | B8: SLRP - Centralizado | C8: AES ANDES S.A. | D8: Franco Travaglini | E8: 100 | F8: 46164 | G8: Cierre 70% (Preferencia) | H8: 0.5 | I8: =E8*H8 -> 50 | K8: Perdido | N8: =I8*20% -> 10 | P8: =I8*25% -> 12.5 | R8: =I8*15% -> 7.5 | S8: =I8*10% -> 5 | T8: =I8*15% -> 7.5
I9: l | P9: =5*H8 -> 2.5 | T9: =25*H8 -> 12.5
A10: Normativo | B10: SLRP y PDC Centro de Control | C10: Grenergy | D10: Franco Travaglini | E10: 130 | F10: 46170 | G10: Cotización | H10: =50%*M1 -> 0 | I10: =E10*H10*$M$1 -> 0 | N10: =I10/5 -> 0 | O10: =$N$10 -> 0 | P10: =$N$10 -> 0 | Q10: =$N$10 -> 0 | R10: =$N$10 -> 0
I11: I
A12: SCADA | B12: Servicio arriendo de maleta omicron 356 - Synchroteq | C12: Engie Energia Chile S.A. | D12: Kevin Fuentealba | E12: 2 | F12: 46170 | G12: Cierre 90% (Adjudicación Verbal) | H12: 0.9 | I12: =E12*H12 -> 1.8 | K12: Se corre a Julio
A14: PAC | B14: Suministro GPS Kronos | C14: Tecnored S.A. | D14: Kevin Fuentealba | E14: 3 | F14: 46170 | G14: Cierre 90% (Adjudicación Verbal) | H14: 0.9 | I14: =E14*H14 -> 2.7 | K14: OC
A16: PAC | B16: Servicio de Independización de Nucleos | C16: Engie Energia Chile S.A. | D16: Kevin Fuentealba | E16: 7 | F16: 46170 | G16: Cierre 90% (Adjudicación Verbal) | H16: 0.9 | I16: =E16*H16 -> 6.3 | K16: Se corre a Julio
A18: Normativo | B18: Implementación 4 PMUs | C18: ENORCHILE S.A. | D18: Bruno Jofré | E18: 130 | F18: 46171 | G18: Cierre | H18: 0.5 | I18: =E18*H18 -> 65 | K18: Se corre a Junio | N18: =I18*10% -> 6.5 | O18: =I18*10% -> 6.5 | P18: =I18*15% -> 9.75 | R18: =I18*40% -> 26 | S18: =I18*15% -> 9.75 | T18: =I18*10% -> 6.5
I19: l | O19: =1.6*H18 -> 0.8 | R19: =19.8*H18 -> 9.9 | S19: =34.6*H18 -> 17.3 | T19: =H18*14.6 -> 7.3
A20: Normativo | B20: Eletrans Implementación 2 x PMU | C20: Eletrans III S.A | D20: Bruno Jofré | E20: 80 | F20: 46171 | G20: Cierre 70% (Preferencia) | H20: 0.7 | I20: =E20*H20 -> 56 | K20: Se corre a Junio | O20: =E20*H20*20% -> 11.2 | P20: =E20*H20*25% -> 14 | S20: =E20*H20*50% -> 28
I21: l | N21: =H20*1.5 -> 1.05 | Q21: =H20*2.5 -> 1.75 | R21: =H20*1.4 -> 0.98 | S21: =H20*23 -> 16.1
A22: Normativo | B22: Adecuación EDAC | C22: Eka Chile S.A. | D22: Kevin Fuentealba | E22: 12 | F22: 46171 | G22: Cierre | H22: 0.3 | I22: =E22*H22 -> 3.6 | K22: Se corre a Junio
A24: Normativo | B24: Suministro Gabinetes para PMU | C24: CGE TRANSMISION SA | D24: Bruno Jofré | E24: 20 | F24: 46171 | G24: Cotización | H24: 0.25 | I24: =E24*H24*$M$1 -> 0
A26: Normativo | B26: Integración de PMU Sarco y Aurora | C26: Innergex Energia Renovable S.p.A. | D26: Bruno Jofré | E26: 2 | F26: 46171 | G26: Cierre 60% (CT Cubierto) | H26: 0.7 | I26: =E26*H26 -> 1.4 | K26: Se corre a Julio
A28: Normativo | B28: PMU Domeyko | C28: VERANO EPC SPA | E28: 20 | F28: 46171 | G28: Cotización | H28: 0 | I28: =E28*H28*$M$1 -> 0
A30: Normativo | B30: Implementación 7 PMU | C30: Electrica Puntilla | D30: Franco Travaglini | E30: 140 | F30: 46171 | G30: Posicionamiento | H30: 0.7
A32: Normativo | B32: PMU Zona Centro | C32: TRANSELEC S A | D32: Franco Travaglini | E32: 160 | F32: 46171 | G32: Cierre | H32: 0.7 | I32: =E32*H32 -> 112 | K32: Se corre a Julio | O32: =I32*10% -> 11.2 | S32: =60%*I32 -> 67.2 | T32: =I32*30% -> 33.6
I33: l | N33: =1.4*H32 -> 0.98 | O33: =0.3*H32 -> 0.21 | R33: =9.2*H32 -> 6.44 | S33: =1.1*H32 -> 0.77 | T33: =17*H32 -> 11.9
A34: Normativo | B34: Ampliación PDC 3 Licencias | C34: Acciona Energia Chile S.p.A. | D34: Franco Travaglini | E34: 10 | F34: 46171 | G34: Cierre 70% (Preferencia) | H34: 0.7 | I34: =E34*H34 -> 7 | K34: Se corre a Junio
A36: Normativo | B36: 2 x EDAG + 2 x PMU | C36: Southenergy Spa | D36: Bruno Jofré | E36: 120 | F36: 46171 | G36: Cierre | H36: 0.3 | I36: =E36*H36 -> 36 | K36: Perdido
I37: l
A38: PAC | B38: Suministro RTU SE Balandras | C38: Tecnored S.A. | D38: Kevin Fuentealba | E38: 10 | F38: 46171 | G38: Cierre 90% (Adjudicación Verbal) | H38: 0.9 | I38: =E38*H38 -> 9 | K38: OC
A40: PAC | B40: Servicios Reconectadores Fase 1 | C40: Chilquinta Distribucion S.A. | D40: Kevin Fuentealba | E40: 40 | F40: 46171 | G40: Cierre 90% (Adjudicación Verbal) | H40: 0.9 | I40: =E40*H40 -> 36 | K40: Se corre a Junio
I41: l
A42: Normativo | B42: implementación 18 x PMU | C42: Grupo Saesa | D42: Franco Travaglini | E42: 300 | F42: 46172 | G42: Cierre 60% (CT Cubierto) | H42: 0.7 | I42: =E42*H42 -> 210 | K42: Se corre a Julio | N42: =I42*20% -> 42 | O42: =I42*10% -> 21 | P42: =I42*15% -> 31.5 | Q42: =I42*5% -> 10.5 | T42: =I42*21% -> 44.1 | U42: =I42*9% -> 18.9 | V42: =I42*20% -> 42
I43: l | O43: =1*H42 -> 0.7 | Q43: =9.9*H42 -> 6.93 | R43: =20*H42 -> 14 | S43: =76*H42 -> 53.2 | T43: =4.2*H42 -> 2.94 | U43: =4*H42 -> 2.8 | W43: =44*H42 -> 30.8
A44: SCADA | B44: SCADA Nova - CC | C44: ENAP | D44: Franco Travaglini | E44: 118 | F44: 46172 | G44: Cierre | H44: 0.5 | I44: =E44*H44 -> 59 | K44: Se corre a Junio | N44: =I44/5 -> 11.8 | O44: =$N$44 -> 11.8 | P44: =$N$44 -> 11.8 | Q44: =$N$44 -> 11.8 | R44: =$N$44 -> 11.8
I45: l | O45: =2.4*H44 -> 1.2 | P45: =8.5*H44 -> 4.25 | Q45: =H44*33 -> 16.5 | R45: =H44*4.9 -> 2.45
A46: Normativo | B46: Quantica - Licencias PDC | C46: QUANTICA INGENIERIA SPA | D46: Kevin Fuentealba | E46: 6 | F46: 46199 | G46: Cierre | H46: 0.5 | I46: =E46*H46 -> 3
A48: PAC | B48: Chilquinta - Retrofit de RTU S/E Quilpue | C48: Chilquinta Transmisión S.A. | D48: Kevin Fuentealba | E48: 60 | F48: 46199 | G48: Cotización | H48: 0.6 | I48: =E48*H48*$M$1 -> 0
I49: I
A50: PAC | B50: Servicios RTU SE Balandras | C50: Chilquinta Transmisión S.A. | D50: Kevin Fuentealba | E50: 20 | F50: 46199 | G50: Cierre 90% (Adjudicación Verbal) | H50: 0.9 | I50: =E50*H50 -> 18
I51: l
...

Sheet Proyección Q2 (Junio)
A1: Línea | B1: Oportunidad | C1: Cliente | D1: Vendedor | E1: Ingreso esperado | F1: Cierre esperado | G1: Etapa | H1: Probabilidad | I1: Ingreso con % | K1: Resultado Junio | M1: 0 | N1: Agosto | O1: Septiembre | P1: Octubre | Q1: Noviembre | R1: Diciembre | S1: 46388 | T1: 46419
A2: Normativo | B2: Ingeniería 33 PMUs | C2: Colbún | D2: Francisco Catalán | E2: 75 | F2: 46203 | G2: OC | H2: 1 | I2: =E2*H2 -> 75 | K2: OC
A4: Normativo | B4: Integración 2 PMU | C4: ATLAS Renevable Energy | D4: Franco Travaglini | E4: 13 | F4: 46203 | G4: Cierre | H4: 0.7 | I4: =E4*H4 -> 9.1 | K4: Se corre a Julio
A6: Normativo | B6: Implementación 4 PMUs | C6: ENORCHILE S.A. | D6: Bruno Jofré | E6: 122 | F6: 46203 | G6: Cierre 90% (Adjudicación Verbal) | H6: 0.9 | I6: =E6*H6 -> 109.8 | K6: Se corre a Julio | N6: =I6*10% -> 10.98 | O6: =I6*10% -> 10.98 | P6: =I6*15% -> 16.47 | R6: =I6*40% -> 43.92 | S6: =I6*15% -> 16.47 | T6: =I6*10% -> 10.98
O7: =1.6*H6 -> 1.44 | R7: =19.8*H6 -> 17.82 | S7: =34.6*H6 -> 31.14 | T7: =H6*14.6 -> 13.14
A8: Normativo | B8: Implementacion PDC | C8: ENORCHILE S.A. | D8: Bruno Jofré | E8: 70 | F8: 46203 | G8: Cotización | H8: 0.3 | I8: =E8*H8*$M$1 -> 0
A10: Normativo | B10: Suministro Licencias PDC | C10: Minera Escondida Limitada | D10: Bruno Jofré | E10: 5 | F10: 46203 | G10: Cotización | H10: 0.9 | I10: =E10*H10*$M$1 -> 0
A12: Normativo | B12: licencia PDC Corporativo. | C12: REDEIA CORPORACION SA. | D12: Bruno Jofré | E12: 5.5 | F12: 46203 | G12: Cierre | H12: 0.9 | I12: =E12*H12 -> 4.95 | K12: Se corre a Julio
A14: Normativo | B14: Integración PMU Libelula | C14: Engie Energia Chile S.A. | D14: Franco Travaglini | E14: 12 | F14: 46203 | G14: Cierre 90% (Adjudicación Verbal) | H14: 0.9 | I14: =E14*H14 -> 10.8 | K14: Se corre a Julio
A16: Normativo | B16: licencias Firewall | C16: OCCIDENTAL CHEMICAL CHILE LIMITADA | D16: Franco Travaglini | E16: 2 | F16: 46203 | G16: OC | H16: 1 | I16: =E16*H16 -> 2 | K16: OC
A18: Normativo | B18: Asesoria Normativa SITR | C18: C-SES SPA | D18: Franco Travaglini | E18: 5 | F18: 46203 | G18: Cierre 70% (Preferencia) | H18: 0.7 | I18: =E18*H18 -> 3.5 | K18: Se corre a Julio
A20: Normativo | B20: Quantica - Licencias PDC | C20: QUANTICA INGENIERIA SPA | D20: Bruno Jofré | E20: 5 | F20: 46199 | G20: OC | H20: 1 | I20: =E20*H20 -> 5 | K20: Se corre a Sept
A22: Normativo | B22: PMU Domeyko | C22: VERANO EPC SPA | D22: Franco Travaglini | E22: 20 | F22: 46203 | G22: Cierre | H22: 0.5 | I22: =E22*H22 -> 10 | K22: Se corre a Julio
A24: Normativo | B24: SLRP y PDC Centro de Control | C24: Grenergy | D24: Franco Travaglini | E24: 130 | F24: 46203 | G24: Cierre 90% (Adjudicación Verbal) | H24: 0.9 | I24: =E24*H24 -> 117 | K24: Se corre a Agosto | N24: =I24/5 -> 23.4 | O24: =#REF! -> #REF! | P24: =#REF! -> #REF! | Q24: =#REF! -> #REF! | R24: =#REF! -> #REF!
A26: Normativo | B26: Mtto PDCE 2026 | C26: TRANSELEC S A | D26: Franco Travaglini | E26: 50 | F26: 46203 | G26: Cotización | H26: 0.7 | I26: =E26*H26*$M$1 -> 0 | O26: =I26/2 -> 0 | R26: =O26 -> 0
A28: Normativo | B28: LICENCIAS PDC Corportivo x 2 | C28: WPD Chile | D28: Francisco Catalan | E28: 4 | F28: 46203 | G28: Posicionamiento | H28: 0.3 | I28: =E28*H28*$M$1 -> 0 | P28: =E28*H28*20% -> 0.24 | Q28: =E28*H28*25% -> 0.3 | T28: =E28*H28*50% -> 0.6
A30: Normativo | B30: SITR Linea 7 | C30: EMPRESA DE TRANSPORTES DE PASAJEROS METRO S.A. | D30: Franco Travaglini | E30: 22 | F30: 46203 | G30: Cierre 70% (Preferencia) | H30: 0.5 | I30: =E30*H30 -> 11 | K30: Se corre al 2027
A32: Normativo | B32: Vertice - Suministro GPS para EDAC ENAEX | C32: VERTICE CONSULTORES SPA | D32: Bruno Jofré | E32: 7 | F32: 46203 | G32: Posicionamiento | H32: 0.6 | I32: =E32*H32*$M$1 -> 0
A34: Normativo | B34: PMU Mantos Blancos | C34: Mantos Cooper | D34: Francisco Catalan | E34: 35 | F34: 46203 | G34: Cotización | H34: 0.5 | I34: =E34*H34*$M$1 -> 0
A36: PAC | B36: TEN - Suministro 2 RTU Orion + Configuración | C36: Transmisora Electrica Del Norte S.A. | D36: Kevin Fuentealba | E36: 30 | F36: 46203 | G36: Cierre | H36: 0.1 | I36: =E36*H36 -> 3 | K36: Se corre a Octubre
A38: PAC | B38: Suministro RTU Codelco | C38: Vertice consultores | D38: Kevin Fuentealba | E38: 4 | F38: 46199 | G38: Cierre | H38: 0.25 | I38: =E38*H38 -> 1 | K38: Se corre a Agosto
A40: PAC | B40: Piloto de integración Medidores | C40: AES ANDES S.A. | D40: Franco Travaglini | E40: 3 | F40: 46203 | G40: Posicionamiento | H40: 0.25 | I40: =E40*H40*$M$1 -> 0
A42: PAC | B42: Tecnored - Actualización EDAC y Reemplazo RTU Inchalam | C42: Tecnored S.A. | D42: Kevin Fuentealba | E42: 41 | F42: 46199 | G42: Cierre | H42: 0.15 | I42: =E42*H42 -> 6.15 | K42: Fuera del embudo
A44: PAC | B44: Servicios Reconectadores Fase 1 | C44: Chilquinta Distribucion S.A. | D44: Kevin Fuentealba | E44: 40 | F44: 46203 | G44: OC | H44: 1 | I44: =E44*H44 -> 40 | K44: OC
A46: SCADA | B46: Servicio arriendo de maleta omicron 356 - Synchroteq | C46: Engie Energia Chile S.A. | D46: Kevin Fuentealba | E46: 2 | F46: 46203 | G46: OC | H46: 1 | I46: =E46*H46 -> 2 | K46: OC
A48: PAC | B48: Servicio de Independización de Nucleos | C48: Engie Energia Chile S.A. | D48: Kevin Fuentealba | E48: 7 | F48: 46203 | G48: OC | H48: 1 | I48: =E48*H48 -> 7 | K48: OC
A50: Normativo | B50: Eletrans Implementación 2 x PMU | C50: Eletrans III S.A | D50: Bruno Jofré | E50: 66 | F50: 46171 | G50: OC | H50: 1 | I50: =E50*H50 -> 66 | K50: OC | O50: =E50*H50*20% -> 13.2 | P50: =E50*H50*25% -> 16.5 | S50: =E50*H50*50% -> 33
I51: l | N51: =H50*1.5 -> 1.5 | Q51: =H50*2.5 -> 2.5 | R51: =H50*1.4 -> 1.4 | S51: =H50*23 -> 23
A52: Normativo | B52: Suministro Gabinetes para PMU | C52: CGE TRANSMISION SA | D52: Bruno Jofré | E52: 9 | F52: 46171 | G52: OC | H52: 1 | I52: =E52*H52 -> 9 | K52: OC
G56: PROYECCIÓN ACTUALIZADA AL CIERRE DE MAYO | H56: Abril | I56: ='Proyección Q2 (Abril)'!I133 -> 437 | J56: =Panel!F119 -> 79.454 | K56: =J56-I56 -> -357.546 | N56: =(#REF!+#REF!+#REF!+#REF!+#REF!+N50+N79+#REF!+#REF!+N81+N83+#REF!+#REF!+#REF!+#REF!+#REF!+#REF!+#REF!+#REF!+#REF!+#REF!+#REF!+#REF!+#REF!+#REF!)*1000000 -> #REF! | O56: =(#REF!+#REF!+#REF!+#REF!+#REF!+O50+O79+#REF!+#REF!+O81+O83+#REF!+#REF!+#REF!+#REF!+#REF!+#REF!+#REF!+#REF!+#REF!+#REF!+#REF!+#REF!+#REF!+#REF!)*1000000 -> #REF! | P56: =(#REF!+#REF!+#REF!+#REF!+#REF!+P50+P79+#REF!+#REF!+P81+P83+#REF!+#REF!+#REF!+#REF!+#REF!+#REF!+#REF!+#REF!+#REF!+#REF!+#REF!+#REF!+#REF!+#REF!)*1000000 -> #REF! | Q56: =(#REF!+#REF!+#REF!+#REF!+#REF!+Q50+Q79+#REF!+#REF!+Q81+Q83+#REF!+#REF!+#REF!+#REF!+#REF!+#REF!+#REF!+#REF!+#REF!+#REF!+#REF!+#REF!+#REF!+#REF!)*1000000 -> #REF! | R56: =(#REF!+#REF!+#REF!+#REF!+#REF!+R50+R79+#REF!+#REF!+R81+R83+#REF!+#REF!+#REF!+#REF!+#REF!+#REF!+#REF!+#REF!+#REF!+#REF!+#REF!+#REF!+#REF!+#REF!)*1000000 -> #REF! | S56: =(#REF!+#REF!+#REF!+#REF!+#REF!+S50+S79+#REF!+#REF!+S81+S83+#REF!+#REF!+#REF!+#REF!+#REF!+#REF!+#REF!+#REF!+#REF!+#REF!+#REF!+#REF!+#REF!+#REF!)*1000000 -> #REF! | T56: =(#REF!+#REF!+#REF!+#REF!+#REF!+T50+T79+#REF!+#REF!+T81+T83+#REF!+#REF!+#REF!+#REF!+#REF!+#REF!+#REF!+#REF!+#REF!+#REF!+#REF!+#REF!+#REF!+#REF!)*1000000 -> #REF! | U56: =SUM(N56:T56) -> #REF!
H57: Mayo | I57: =SUM(I46:I83) -> 132.1 | J57: =Panel!F136 -> 535.824 | K57: =J57-I57 -> 354.11 | N57: =(#REF!+#REF!+#REF!+#REF!+#REF!+N51+N80+#REF!+#REF!+N82+N84+#REF!+#REF!+#REF!+#REF!+#REF!+#REF!+#REF!+#REF!+#REF!+#REF!+#REF!+#REF!+#REF!+#REF!)*1000000 -> #REF! | O57: =(#REF!+#REF!+#REF!+#REF!+#REF!+O51+O80+#REF!+#REF!+O82+O84+#REF!+#REF!+#REF!+#REF!+#REF!+#REF!+#REF!+#REF!+#REF!+#REF!+#REF!+#REF!+#REF!+#REF!)*1000000 -> #REF! | P57: =(#REF!+#REF!+#REF!+#REF!+#REF!+P51+P80+#REF!+#REF!+P82+P84+#REF!+#REF!+#REF!+#REF!+#REF!+#REF!+#REF!+#REF!+#REF!+#REF!+#REF!+#REF!+#REF!+#REF!)*1000000 -> #REF! | Q57: =(#REF!+#REF!+#REF!+#REF!+#REF!+Q51+Q80+#REF!+#REF!+Q82+Q84+#REF!+#REF!+#REF!+#REF!+#REF!+#REF!+#REF!+#REF!+#REF!+#REF!+#REF!+#REF!+#REF!+#REF!)*1000000 -> #REF! | R57: =(#REF!+#REF!+#REF!+#REF!+#REF!+R51+R80+#REF!+#REF!+R82+R84+#REF!+#REF!+#REF!+#REF!+#REF!+#REF!+#REF!+#REF!+#REF!+#REF!+#REF!+#REF!+#REF!+#REF!)*1000000 -> #REF! | S57: =(#REF!+#REF!+#REF!+#REF!+#REF!+S51+S80+#REF!+#REF!+S82+S84+#REF!+#REF!+#REF!+#REF!+#REF!+#REF!+#REF!+#REF!+#REF!+#REF!+#REF!+#REF!+#REF!+#REF!)*1000000 -> #REF! | T57: =(#REF!+#REF!+#REF!+#REF!+#REF!+T51+T80+#REF!+#REF!+T82+T84+#REF!+#REF!+#REF!+#REF!+#REF!+#REF!+#REF!+#REF!+#REF!+#REF!+#REF!+#REF!+#REF!+#REF!)*1000000 -> #REF! | U57: =SUM(N57:T57) -> #REF!
H58: Junio | I58: =SUM(I2:I52) -> 492.3 | J58: =Panel!F150 -> 237.777 | K58: =J58-I58 -> -254.523
A60: Normativo | B60: PMU | C60: Barrick | D60: Bruno Jofré | E60: 42 | F60: Mayo | G60: Cierre | H60: 0.9 | I60: =E60*H60 -> 37.8 | N60: =I60*20% -> 7.56 | O60: =I60*25% -> 9.45 | R60: =I60*50% -> 18.9 | S60: =I60*5% -> 1.89
O61: =0.9*H60 -> 0.81 | R61: =H60*7 -> 6.3 | S61: =H60*10 -> 9
A62: Normativo | B62: Suministro 10 PMU y PDC | C62: Enlasa | D62: Francisco Catalán | E62: 237 | F62: 46203 | G62: Cierre | H62: 0.5 | I62: =E62*H62 -> 118.5 | P62: =I62*10% -> 11.85 | Q62: =I62*15% -> 17.775 | R62: =I62*20% -> 23.7 | T62: =I62*20% -> 23.7
O63: =1.4*H62 -> 0.7 | P63: =H62*2.6 -> 1.3 | R63: =21.5*H62 -> 10.75 | S63: =3.8*H62 -> 1.9 | T63: =H62*43.5 -> 21.75
A64: Scada | B64: Retrofit SCADA | C64: CPP | D64: Francisco Catalán | E64: 94 | F64: 46264 | G64: Cotización | H64: 0 | I64: =E64*H64 -> 0 | R64: =E64*H64*70%*35% -> 0 | S64: =65%*20%*E64*H64 -> 0 | T64: =E64*H64*65%*25% -> 0
R65: =H64*0.3 -> 0 | S65: =R65 -> 0 | T65: =S65 -> 0
N66: =#REF!+#REF!+#REF!+#REF!+#REF!+N50+N79+#REF!+#REF!+N81+N83+#REF!+#REF!+#REF!+#REF!+#REF!+#REF!+#REF!+#REF!+#REF!+#REF!+#REF!+#REF!+#REF!+#REF! -> #REF! | O66: =#REF!+#REF!+#REF!+#REF!+#REF!+O50+O79+#REF!+#REF!+O81+O83+#REF!+#REF!+#REF!+#REF!+#REF!+#REF!+#REF!+#REF!+#REF!+#REF!+#REF!+#REF!+#REF!+#REF! -> #REF! | P66: =#REF!+#REF!+#REF!+#REF!+#REF!+P50+P79+#REF!+#REF!+P81+P83+#REF!+#REF!+#REF!+#REF!+#REF!+#REF!+#REF!+#REF!+#REF!+#REF!+#REF!+#REF!+#REF!+#REF! -> #REF! | Q66: =#REF!+#REF!+#REF!+#REF!+#REF!+Q50+Q79+#REF!+#REF!+Q81+Q83+#REF!+#REF!+#REF!+#REF!+#REF!+#REF!+#REF!+#REF!+#REF!+#REF!+#REF!+#REF!+#REF!+#REF! -> #REF! | R66: =#REF!+#REF!+#REF!+#REF!+#REF!+R50+R79+#REF!+#REF!+R81+R83+#REF!+#REF!+#REF!+#REF!+#REF!+#REF!+#REF!+#REF!+#REF!+#REF!+#REF!+#REF!+#REF!+#REF! -> #REF! | S66: =#REF!+#REF!+#REF!+#REF!+#REF!+S50+S79+#REF!+#REF!+S81+S83+#REF!+#REF!+#REF!+#REF!+#REF!+#REF!+#REF!+#REF!+#REF!+#REF!+#REF!+#REF!+#REF!+#REF! -> #REF! | T66: =#REF!+#REF!+#REF!+#REF!+#REF!+T50+T79+#REF!+#REF!+T81+T83+#REF!+#REF!+#REF!+#REF!+#REF!+#REF!+#REF!+#REF!+#REF!+#REF!+#REF!+#REF!+#REF!+#REF! -> #REF!
N68: =(N60+N62+N64)*1000000 -> 7560000 | O68: =(O60+O62+O64)*1000000 -> 9450000 | P68: =(P60+P62+P64)*1000000 -> 11850000 | Q68: =(Q60+Q62+Q64)*1000000 -> 17775000 | R68: =(R60+R62+R64)*1000000 -> 42600000 | S68: =(S60+S62+S64)*1000000 -> 1890000 | T68: =(T60+T62+T64)*1000000 -> 23700000 | U68: =SUM(N68:T68) -> 1.14825e+08
...

Sheet Proyección Q3 (Julio)
A1: Línea | B1: Oportunidad | C1: Cliente | D1: Vendedor | E1: Ingreso esperado | F1: Cierre esperado | G1: Etapa | H1: Probabilidad | I1: Ingreso con % | K1: Resultado Julio | L1: 0 | M1: Agosto | N1: Septiembre | O1: Octubre | P1: Noviembre | Q1: Diciembre | R1: 46388 | S1: 46419 | T1: 46447 | U1: 46478 | V1: 46508 | W1: 46539 | X1: 46569
A2: Normativo | B2: PMU Domeyko | C2: VERANO EPC SPA | D2: Bruno Jofré | E2: 32 | F2: 46213 | G2: Cierre 90% (Adjudicación Verbal) | H2: 1 | I2: =E2*H2 -> 32 | N2: =I2*10% -> 3.2 | O2: =I2*10% -> 3.2 | R2: =I2*30% -> 9.6 | S2: =I2*50% -> 16
O3: =H2*0.4 -> 0.4 | Q3: =1.6*H2 -> 1.6 | R3: =4.9*H2 -> 4.9 | S3: =5.3*H2 -> 5.3 | T3: =H2*1.7 -> 1.7
A4: Normativo | B4: licencia PDC Corporativo. | C4: REDEIA CORPORACION SA. | D4: Bruno Jofré | E4: 5.5 | F4: 46213 | G4: Cierre | H4: 1 | I4: =E4*H4 -> 5.5 | N4: =I4 -> 5.5
O5: =I4*0.85 -> 4.675
A6: Normativo | B6: Pruebas PRS-SCADA | C6: Enfragen , Llc | D6: Francisco Catalan | E6: 28 | F6: 46227 | G6: Cierre 90% (Adjudicación Verbal) | H6: 1 | I6: =E6*H6 -> 28
A8: Normativo | B8: Implementación 4 PMUs | C8: ENORCHILE S.A. | D8: Bruno Jofré | E8: 102 | F8: 46234 | G8: Cierre 90% (Adjudicación Verbal) | H8: 0.9 | I8: =E8*H8 -> 91.8 | N8: =I8*10% -> 9.18 | O8: =I8*10% -> 9.18 | P8: =I8*15% -> 13.77 | R8: =I8*40% -> 36.72 | S8: =I8*15% -> 13.77 | T8: =I8*10% -> 9.18
O9: =H8*1.5 -> 1.35 | R9: =4.5*H8 -> 4.05 | S9: =30*H8 -> 27 | T9: =H8*14 -> 12.6
A10: Normativo | B10: Pruebas PRS | C10: SAESA | D10: Francisco Catalan | E10: 20 | F10: 46234 | G10: Cotización | H10: 0.5 | I10: =E10*H10*$L$1 -> 0
A12: Normativo | B12: Integración 2 PMU a PDC | C12: Acciona Energia Chile S.p.A. | D12: Franco Travaglini | E12: 14 | F12: 46234 | G12: Cierre | H12: 0.5 | I12: =E12*H12 -> 7 | J12: No tiene flujo
A14: Normativo | B14: Integración PMU Libelula | C14: Engie Energia Chile S.A. | D14: Franco Travaglini | E14: 12 | F14: 46234 | G14: Cierre 90% (Adjudicación Verbal) | H14: 0.9 | I14: =E14*H14 -> 10.8 | J14: No tiene flujo
A16: Normativo | B16: Asesoria Normativa SITR | C16: C-SES SPA | D16: Franco Travaglini | E16: 5 | F16: 46234 | G16: Cierre 70% (Preferencia) | H16: 0.7 | I16: =E16*H16 -> 3.5 | J16: No tiene flujo
A18: Normativo | B18: Implementación 7 PMU | C18: Electrica Puntilla | D18: Francisco Catalan | E18: 190 | F18: 46234 | G18: Cierre 70% (Preferencia) | H18: 0.9 | I18: =E18*H18 -> 171 | J18: Falta flujo
A20: Normativo | B20: PMU Zona Centro | C20: TRANSELEC S A | D20: Franco Travaglini | E20: 160 | F20: 46234 | G20: Cierre | H20: 0.7 | I20: =E20*H20 -> 112 | N20: =I20*10% -> 11.2 | S20: =I20*60% -> 67.2 | T20: =I20*30% -> 33.6
M21: =H20*1.4 -> 0.98 | N21: =H20*0.3 -> 0.21 | Q21: =H20*9.2 -> 6.44 | R21: =H20*1.1 -> 0.77 | S21: =H20*18 -> 12.6
A22: Normativo | B22: Integración PMU Arrayan a Maitencillo | C22: Sonnedix Chile Holding S.p.A. | D22: Bruno Jofré | E22: 8 | F22: 46234 | G22: Cierre | H22: 0.3 | I22: =E22*H22 -> 2.4
A24: PAC | B24: Servicios Protecciones | C24: Transquinta | D24: Kevin Fuentealba | E24: 10 | F24: 46234 | G24: Cierre | H24: 0.6 | I24: =E24*H24 -> 6
A26: PAC | B26: Servicios Protecciones | C26: CTNG | D26: Kevin Fuentealba | E26: 6 | F26: 46234 | G26: Cierre | H26: 0.6 | I26: =E26*H26 -> 3.6
A28: PAC | B28: Servicios Protecciones | C28: Eletrans III | D28: Kevin Fuentealba | E28: 8 | F28: 46234 | G28: Cierre | H28: 0.6 | I28: =E28*H28 -> 4.8
A30: PAC | B30: Servicios Protecciones | C30: Eletrans I | D30: Kevin Fuentealba | E30: 13 | F30: 46234 | G30: Cierre | H30: 0.6 | I30: =E30*H30 -> 7.8
A32: PAC | B32: Servicios Protecciones | C32: Transquinta | D32: Kevin Fuentealba | E32: 3 | F32: 46234 | G32: Cierre | H32: 0.6 | I32: =E32*H32 -> 1.8
A34: SCADA | B34: Contrato de mantenimiento | C34: Cementos Melon | D34: Francisco Catalan | E34: 31 | F34: 46234 | G34: Cierre 90% (Adjudicación Verbal) | H34: 0.7 | I34: =E34*H34 -> 21.7 | M34: =$I$34/24 -> 0.90416667 | N34: =$I$34/24 -> 0.90416667 | O34: =$I$34/24 -> 0.90416667 | P34: =$I$34/24 -> 0.90416667 | Q34: =$I$34/24 -> 0.90416667 | R34: =$I$34/24 -> 0.90416667 | S34: =$I$34/24 -> 0.90416667 | T34: =$I$34/24 -> 0.90416667 | ... X34: =$I$34/24 -> 0.90416667
A36: SCADA | B36: Estación de Ingeniería | C36: Gestion de Proyectos Electricos S.A. | D36: Franco Travaglini | E36: 8 | F36: 46234 | G36: Cierre | H36: 0.7 | I36: =E36*H36 -> 5.6 | J36: No tiene flujo
A38: SCADA | B38: Licencia SQL | C38: Cooperativa Regional Electrica Llanquihue Limitada | D38: Franco Travaglini | E38: 1 | F38: 46234 | G38: Cierre | H38: 1 | I38: =E38*H38 -> 1 | J38: No tiene flujo
A40: SCADA | B40: Retrofit Lomas Bayas | C40: Lomas Bayas | D40: Francisco Catalan | E40: 158 | F40: 46234 | G40: Cierre | H40: 0.3 | I40: =E40*H40 -> 47.4 | J40: Flujo
A42: Normativo | B42: Implementación 2 PMUs | C42: X-elio | D42: Bruno Jofré | E42: 60 | F42: 46262 | G42: Cierre 60% (CT Cubierto) | H42: 0.3 | I42: =E42*H42 -> 18
A44: Normativo | B44: SLRP y PDC Centro de Control | C44: Grenergy | D44: Franco Travaglini | E44: 130 | F44: 46262 | G44: Cierre 90% (Adjudicación Verbal) | H44: 0.9 | I44: =E44*H44 -> 117 | J44: Flujo
A46: PAC | B46: Retrofit de RTU SE Polpaico | C46: TRANSELEC S A | D46: Kevin Fuentealba | E46: 150 | F46: 46262 | G46: Cierre | H46: 0.3 | I46: =E46*H46 -> 45 | O46: =I46*72%*15% -> 4.86 | Q46: =I46*72%*15% -> 4.86 | R46: =I46*72%*20% -> 6.48 | V46: =I46*72%*25% -> 8.1 | W46: =I46*72%*10% -> 3.24 | X46: =I46*72%*10% -> 3.24 | Y46: =I46*72%*10% -> 3.24
O47: =H46*4.1 -> 1.23 | S47: =H46*7 -> 2.1 | T47: =H46*4.5 -> 1.35 | U47: =H46*35.1 -> 10.53 | V47: =H46*10.8 -> 3.24 | W47: =H46*3.5 -> 1.05 | X47: =H46*23 -> 6.9 | Y47: =H46*2.6 -> 0.78 | Z47: =H46*3.5 -> 1.05
A48: PAC | B48: Guacolda - Eficiencia Energetica (Medidores) | C48: Guacolda Energia SpA | D48: Kevin Fuentealba | E48: 55 | F48: 46262 | G48: Cierre | H48: 0.25 | I48: =E48*H48 -> 13.75
A50: PAC | B50: CMP - Mina El Romeral - Implementación RTU / SCADA Local | C50: Compania Minera del Pacifico S.A. | D50: Kevin Fuentealba | E50: 60 | F50: 46262 | G50: Cotización | H50: 0.3 | I50: =E50*H50*$L$1 -> 0
A52: Normativo | B52: implementación 18 x PMU | C52: Grupo Saesa | D52: Franco Travaglini | E52: 300 | F52: 46265 | G52: Cierre | H52: 0.3 | I52: =E52*H52 -> 90 | O52: =I52*20% -> 18 | P52: =I52*10% -> 9 | Q52: =I52*15% -> 13.5 | R52: =I52*5% -> 4.5 | U52: =I52*21% -> 18.9 | V52: =I52*9% -> 8.1 | W52: =I52*20% -> 18
P53: =H52*1 -> 0.3 | R53: =H52*10 -> 3 | S53: =H52*20 -> 6 | T53: =H52*76 -> 22.8 | U53: =H52*4.2 -> 1.26 | V53: =H52*4 -> 1.2 | X53: =H52*44 -> 13.2
A54: Normativo | B54: Licencias PDC LOCAL Y CORPO | C54: Colbun S.A. | D54: Francisco Catalan | E54: 220 | F54: 46265 | G54: Cotización | H54: 0.3 | I54: =E54*H54*$L$1 -> 0
A56: Normativo | B56: Suministro Licencias PDC | C56: Minera Escondida Limitada | D56: Bruno Jofré | E56: 5 | F56: 46265 | G56: Cierre | H56: 0.9 | I56: =E56*H56 -> 4.5
A58: Normativo | B58: Sonnedix Integración 7 PMU | C58: Sonnedix | D58: Franco Travaglini | E58: 50 | F58: 46265 | G58: Cierre | H58: 0.5 | I58: =E58*H58 -> 25 | O58: =I58*23%*15%+I58*37%*20% -> 2.7125 | P58: =I58*23%*25%+I58*25% -> 7.6875 | Q58: =I58*23%*40%+I58*37%*80%+I58*14% -> 13.2 | R58: =I58*23%*15% -> 0.8625 | S58: =I58*23%*5% -> 0.2875
R59: =H58*28.5 -> 14.25 | S59: =H58*15 -> 7.5
A60: Normativo | B60: Suministro e implementación 2 PMU | C60: Consorcio Santa Marta S.A. | D60: Francisco Catalan | E60: 55 | F60: 46265 | G60: Cierre | H60: 0.1 | I60: =E60*H60 -> 5.5
A62: Normativo | B62: Mtto PDCE 2026 | C62: TRANSELEC S A | D62: Franco Travaglini | E62: 50 | F62: 46265 | G62: Cierre | H62: 0.7 | I62: =E62*H62 -> 35 | O62: =I62*50% -> 17.5
A64: Normativo | B64: Prime Energía 21 PMU y PDC | C64: Enfragen , Llc | D64: Franco Travaglini | E64: 480 | F64: 46265 | G64: Cierre | H64: 0.3 | I64: =E64*H64 -> 144 | O64: =I64*45%*25%+I64*55%*30% -> 39.96 | R64: =I64*45%*15%+I64*55%*50% -> 49.32 | S64: =I64*45%*20% -> 12.96 | W64: =I64*45%*25% -> 16.2 | AA64: =I64*45%*10%+I64*55%*20% -> 22.32 | AB64: =I64*45%*5% -> 3.24
...

Sheet Flujo
A1: Línea | B1: Oportunidad | C1: Cliente | D1: Vendedor | E1: Ingreso esperado | F1: Cierre esperado | G1: Etapa | H1: Probabilidad | I1: Ingreso con % | J1: Nota | K1: Marzo | L1: Abril | M1: Mayo | N1: Junio | O1: Julio | P1: Agosto | Q1: Septiembre | R1: Octubre | S1: Noviembre | T1: Diciembre
A2: PAC | B2: Transelec - Retrofit de Protecciones | C2: TRANSELEC S A | D2: Kevin Fuentealba | E2: 120 | F2: 46066 | G2: Cierre 90% (Adjudicación Verbal) | H2: 1 | I2: =E2*H2 -> 120 | J2: En backlog
A3: PAC | B3: Transelec - Retrofit de Protecciones 2026 | C3: TRANSELEC S A | D3: Kevin Fuentealba | E3: 120 | F3: 46081 | G3: Cierre 70% (Preferencia) | H3: 0.7 | I3: =E3*H3 -> 84 | J3: Añadir flujo
A4: Egresos
A5: Normativo | B5: Mantenimiento | C5: Celeo | D5: Franco Travaglini | E5: 64 | F5: 46081 | G5: Cierre | H5: 0.9 | I5: =E5*H5 -> 57.6 | L5: =I5 -> 57.6
A6: Normativo | B6: 6 PMU | C6: CGE | D6: Bruno Jofré | E6: 100 | F6: 46081 | G6: Cierre | H6: 0.9 | I6: =E6*H6 -> 90 | J6: En backlog
A7: SCADA | B7: Drivers Mantos Blancos | C7: MANTOS COPPER S.A. | D7: Franco Travaglini | E7: 12 | F7: 46112 | G7: Cierre | H7: 0.5 | I7: =E7*H7 -> 6
A8: PAC | B8: Reemplazo SAS Hualpén- Transelec | C8: TRANSELEC S A | D8: Kevin Fuentealba | E8: 736 | F8: 46112 | G8: Cierre 60% (CT Cubierto) | H8: 0.6 | I8: =E8*H8 -> 441.6 | J8: Añadir flujo
A9: Egresos
A10: PAC | B10: Chilquinta - Suministro Relé NR SE Damascal | C10: Chilquinta | D10: Kevin Fuentealba | E10: 15 | F10: 46112 | G10: Cierre 60% (CT Cubierto) | H10: 0.6 | I10: =E10*H10 -> 9
A11: Normativo | B11: Visita de levantamiento | C11: Agrosuper | D11: Bruno Jofré | E11: 3 | F11: 46080 | G11: Cierre | H11: 0.9 | I11: =E11*H11 -> 2.7
A12: Normativo | B12: Acondicionamiento del SITR | C12: Mantoverde | D12: Francisco Catalan | E12: 25 | F12: 46080 | G12: Cierre | H12: 1 | I12: =E12*H12 -> 25 | J12: En backlog
A13: Normativo | B13: Implementación 2 PMU | C13: Pacific Hydro | D13: Bruno Jofré | E13: 50 | F13: 46080 | G13: Cierre | H13: 1 | I13: =E13*H13 -> 50 | J13: En backlog
A14: Normativo | B14: Implementación 2 PMU | C14: Tinguiririca | D14: Bruno Jofré | E14: 91 | F14: 46080 | G14: Cierre | H14: 1 | I14: =E14*H14 -> 91
A15: Normativo | B15: Visita de levantamiento | C15: Cementos Melon | D15: Francisco Catalan | E15: 3 | F15: 46081 | G15: Cierre 60% (CT Cubierto) | H15: 0.5 | I15: =E15*H15 -> 1.5
A16: Normativo | B16: 3 Licencias PDC | C16: Acciona | D16: Franco Travaglini | E16: 10 | F16: 46081 | G16: Cierre | H16: 0.9 | I16: =E16*H16 -> 9
